Workbook

Sheet Details
A1: Name | B1: Handicap | C1: A Course Stroking - Fourball | D1: A Course Stroking - Singles | E1: A Course Stroking - Singles 9A | F1: 9B Stroking | H1: Anuj | K1: Ashu B'ram | N1: Ashu Jain | Q1: Bharat | T1: Biku | W1: Gaggy | Z1: Gaurav | AC1: Jaideep | AF1: Jaivi | AI1: Imran | AL1: Kartik B'ram | AO1: Luvy | AR1: Nutty | AU1: Poky | AX1: Pran | BA1: Raul | BD1: Rishab | BG1: Sam | BJ1: Sikki | BM1: Utkarsh | BP1: Vijit | BT1: Vishal
B2: A | C2: B | D2: C | E2: C | F2: D | H2: Scores | I2: Handicap | K2: Scores | L2: Handicap | N2: Scores | O2: Handicap | Q2: Scores | R2: Handicap | T2: Scores | U2: Handicap | W2: Scores | X2: Handicap | Z2: Scores | AA2: Handicap | AC2: Scores | AD2: Handicap | AF2: Scores | AG2: Handicap | AI2: Scores | AJ2: Handicap | AL2: Scores | AM2: Handicap | AO2: Scores | AP2: Handicap | AR2: Scores | AS2: Handicap | AU2: Scores | AV2: Handicap | AX2: Scores | AY2: Handicap | BA2: Scores | BB2: Handicap | BD2: Scores | BE2: Handicap | BG2: Scores | BH2: Handicap | BJ2: Scores | BK2: Handicap | BM2: Scores | BN2: Handicap | BP2: Scores | BQ2: Handicap | BT2: Scores | BU2: Handicap
A3: Poky | B3: =Details!AV3 -> 4.8333333 | C3: 0 | D3: =(B3-$B$3) -> 0 | E3: =(B4-$B$4)/2 -> 0 | F3: =(B4-$B$4)*0.6/2 -> 0 | I3: {=SUM(SMALL(H5:H16,{1,2,3,4,5,6}))/6} -> 11.533333 | L3: {=SUM(SMALL(K5:K16,{1,2,3,4,5,6}))/6} -> 13.666667 | O3: {=SUM(SMALL(N5:N16,{1,2,3,4,5,6}))/6} -> 14.333333 | R3: {=SUM(SMALL(Q5:Q16,{1,2,3,4,5,6}))/6} -> 12.5 | U3: {=SUM(SMALL(T5:T16,{1,2,3,4,5,6}))/6} -> 10.633333 | X3: {=SUM(SMALL(W5:W16,{1,2,3,4,5,6}))/6} -> 15.333333 | AA3: {=SUM(SMALL(Z5:Z16,{1,2,3,4,5,6}))/6} -> 11.166667 | AD3: {=SUM(SMALL(AC5:AC16,{1,2,3,4,5,6}))/6} -> 14.928571 | AG3: {=SUM(SMALL(AF5:AF16,{1,2,3,4,5,6}))/6} -> 11.666667 | AJ3: {=SUM(SMALL(AI5:AI16,{1,2,3,4,5,6}))/6} -> 10.933333 | AM3: {=SUM(SMALL(AL5:AL16,{1,2,3,4,5,6}))/6} -> 12.333333 | AP3: {=SUM(SMALL(AO5:AO16,{1,2,3,4,5,6}))/6} -> 12.833333 | AS3: {=SUM(SMALL(AR5:AR16,{1,2,3,4,5,6}))/6} -> 5.1666667 | AV3: {=SUM(SMALL(AU5:AU16,{1,2,3,4,5,6}))/6} -> 4.8333333 | AY3: {=SUM(SMALL(AX5:AX16,{1,2,3,4,5,6}))/6} -> 15.738095 | BB3: {=SUM(SMALL(BA5:BA16,{1,2,3,4,5,6}))/6} -> 5.1666667 | BE3: {=SUM(SMALL(BD5:BD16,{1,2,3,4,5,6}))/6} -> 13.142857 | BH3: {=SUM(SMALL(BG5:BG16,{1,2,3,4,5,6}))/6} -> 13.375 | BK3: {=SUM(SMALL(BJ5:BJ16,{1,2,3,4,5,6}))/6} -> 10.416667 | BN3: {=SUM(SMALL(BM5:BM16,{1,2,3,4,5,6}))/6} -> 11.333333 | BQ3: {=SUM(SMALL(BP5:BP16,{1,2,3,4,5,6}))/6} -> 12.137255 | BU3: {=SUM(SMALL(BT5:BT16,{1,2,3,4,5,6}))/6} -> 10.833333
A4: Raul | B4: =Details!BB3 -> 5.1666667 | C4: =D4*0.75 -> 0.25 | D4: =(B4-$B$3) -> 0.33333333 | E4: =(B3-$B$4)/2 -> -0.16666667 | F4: =(B3-$B$4)*0.6/2 -> -0.1
A5: Nutty | B5: =Details!AS3 -> 5.1666667 | C5: =D5*0.75 -> 0.25 | D5: =(B5-$B$3) -> 0.33333333 | E5: =(#REF!-$B$4)/2 -> #REF! | F5: =(#REF!-$B$4)*0.6/2 -> #REF! | H5: 8 | K5: 24 | N5: 16 | Q5: 14 | T5: 10 | W5: 24 | Z5: 10 | AC5: =9*18/14 -> 11.571429 | AF5: 14 | AI5: 13 | AL5: 16 | AO5: 18 | AR5: 6 | AU5: 3 | AX5: 15 | BA5: 4 | BD5: 16 | BG5: 13 | BJ5: 5 | BM5: =10*18/14 -> 12.857143 | BP5: 13 | BR5: April 3 - DGC Blue | BT5: 14
A6: Sikki | B6: =Details!BK3 -> 10.416667 | C6: =D6*0.75 -> 4.1875 | D6: =(B6-$B$3) -> 5.5833333 | E6: =(B5-$B$4)/2 -> 0 | F6: =(B5-$B$4)*0.6/2 -> 0 | H6: 11 | K6: 9 | N6: 14 | Q6: 18 | T6: 18 | W6: 19 | Z6: 17 | AC6: 16 | AF6: 13 | AI6: 11 | AL6: 16 | AO6: 20 | AR6: 6 | AU6: 8 | AX6: 21 | BA6: 12 | BD6: 18 | BG6: 18 | BJ6: 18 | BM6: 11 | BP6: 12 | BR6: April 1 - DGC Blue | BT6: 18
A7: Biku | B7: =Details!U3 -> 10.633333 | C7: =D7*0.75 -> 4.35 | D7: =(B7-$B$3) -> 5.8 | E7: =(B6-$B$4)/2 -> 2.625 | F7: =(B6-$B$4)*0.6/2 -> 1.575 | H7: 20 | K7: 15 | N7: 20 | Q7: 16 | T7: 12 | W7: 21 | Z7: 16 | AC7: 14 | AF7: 13 | AI7: 17 | AL7: 17 | AO7: 19 | AR7: 9 | AU7: 15 | AX7: =12*18/14 -> 15.428571 | BA7: 5 | BD7: 17 | BG7: 18 | BJ7: 8 | BM7: 8 | BP7: 18 | BR7: March 30 - DGC Blue | BT7: 14
A8: Vishal | B8: =Details!BU3 -> 10.833333 | C8: =D8*0.75 -> 4.5 | D8: =(B8-$B$3) -> 6 | E8: =(B8-$B$4)/2 -> 2.8333333 | F8: =(B8-$B$4)*0.6/2 -> 1.7 | H8: 13 | K8: 14 | N8: 15 | Q8: 14 | T8: 8 | W8: 19 | Z8: 16 | AC8: 15 | AF8: 12 | AI8: 12 | AL8: 15 | AO8: 17 | AR8: 9 | AU8: 10 | AX8: 20 | BA8: 7 | BD8: 9 | BG8: 20 | BJ8: =15*1.1 -> 16.5 | BM8: 11 | BP8: =14*18/17 -> 14.823529 | BR8: March 27 - JP Yellow | BT8: 15
A9: Gaurav | B9: =Details!AA3 -> 11.166667 | C9: =D9*0.75 -> 4.75 | D9: =(B9-$B$3) -> 6.3333333 | E9: =(B9-$B$4)/2 -> 3 | F9: =(B9-$B$4)*0.6/2 -> 1.8 | H9: =16*1.2 -> 19.2 | K9: 20 | N9: 15 | Q9: 16 | T9: 15 | W9: 18 | Z9: 14 | AC9: 15 | AF9: 16 | AI9: 11 | AL9: 24 | AO9: 12 | AR9: 8 | AU9: 8 | AX9: 19 | BA9: 5 | BD9: =10*18/14 -> 12.857143 | BG9: 16 | BJ9: =15*0.9 -> 13.5 | BM9: 18 | BP9: =16*1.1 -> 17.6 | BR9: March 22 - Lado Black | BT9: 16
A10: Utkarsh | B10: =Details!BN3 -> 11.333333 | C10: =D10*0.75 -> 4.875 | D10: =(B10-$B$3) -> 6.5 | E10: =(B10-$B$4)/2 -> 3.0833333 | F10: =(B10-$B$4)*0.6/2 -> 1.85 | H10: =11*1.2 -> 13.2 | K10: 17 | N10: 23 | Q10: 20 | T10: 11 | W10: 13 | Z10: =11*18/14 -> 14.142857 | AC10: 19 | AF10: 16 | AI10: 15 | AL10: 12 | AO10: 15 | AR10: =13*0.8 -> 10.4 | AU10: 7 | AX10: 20 | BA10: 8 | BD10: 19 | BG10: 15 | BJ10: 10 | BM10: 17 | BP10: =16*1.1 -> 17.6 | BR10: March 20 - JP Yellow | BT10: 13
A11: Anuj | B11: =Details!I3 -> 11.533333 | C11: =D11*0.75 -> 5.025 | D11: =(B11-$B$3) -> 6.7 | E11: =(B11-$B$4)/2 -> 3.1833333 | F11: =(B11-$B$4)*0.6/2 -> 1.91 | H11: 14 | K11: 17 | N11: 22 | Q11: 16 | T11: =11*1.1 -> 12.1 | W11: 16 | Z11: 14 | AC11: 22 | AF11: 18 | AI11: 15 | AL11: 13 | AO11: 16 | AR11: 6 | AU11: 6 | AX11: 21 | BA11: 7 | BD11: 13 | BG11: 23 | BJ11: 20 | BM11: 16 | BP11: =14*1.1 -> 15.4 | BR11: March 15 - Lado Black | BT11: 10
A12: Jaivi | B12: =Details!AG3 -> 11.666667 | C12: =D12*0.75 -> 5.125 | D12: =(B12-$B$3) -> 6.8333333 | E12: =(#REF!-$B$4)/2 -> #REF! | F12: =(#REF!-$B$4)*0.6/2 -> #REF! | H12: 15 | K12: 14 | N12: 16 | Q12: 15 | T12: 18 | W12: 10 | Z12: 13 | AC12: =19*1.1 -> 20.9 | AF12: 13 | AI12: 13 | AL12: 14 | AO12: 15 | AR12: 6 | AU12: 4 | AX12: 16 | BA12: 3 | BD12: 16 | BG12: 13 | BJ12: 18 | BM12: 20 | BP12: =7*18/14 -> 9 | BR12: March 12 - JP Yellow | BT12: 9
A13: Vijit | B13: =Details!BQ3 -> 12.137255 | C13: =D13*0.75 -> 5.4779412 | D13: =(B13-$B$3) -> 7.3039216 | E13: =(B12-$B$4)/2 -> 3.25 | F13: =(B12-$B$4)*0.6/2 -> 1.95 | H13: 15 | K13: 24 | N13: 18 | Q13: =9 -> 9 | T13: 19 | W13: 22 | Z13: 14 | AC13: =23*0.8 -> 18.4 | AF13: 18 | AI13: 15 | AL13: 12 | AO13: 14 | AR13: 13 | AU13: 7 | AX13: 15 | BA13: 15 | BD13: 14 | BG13: 10 | BJ13: 22 | BM13: 11 | BP13: 10 | BR13: March 15 - Lado Black | BT13: 9
A14: Kartk B'ram | B14: =Details!AM3 -> 12.333333 | C14: =D14*0.75 -> 5.625 | D14: =(B14-$B$3) -> 7.5 | E14: =(B13-$B$4)/2 -> 3.4852941 | F14: =(B13-$B$4)*0.6/2 -> 2.0911765 | H14: 21 | K14: 14 | N14: 18 | Q14: 18 | T14: 18 | W14: 16 | Z14: 13 | AC14: 18 | AF14: 8 | AI14: 11 | AL14: 12 | AO14: 16 | AR14: 17 | AU14: 5 | AX14: 18 | BA14: 12 | BD14: 18 | BG14: 18 | BJ14: 13 | BM14: =16*1.1 -> 17.6 | BP14: 20 | BR14: March 5 - DGC Blue | BT14: 18
A15: Bharat | B15: =Details!R3 -> 12.5 | C15: =D15*0.75 -> 5.75 | D15: =(B15-$B$3) -> 7.6666667 | E15: =(B14-$B$4)/2 -> 3.5833333 | F15: =(B14-$B$4)*0.6/2 -> 2.15 | H15: 10 | K15: 20 | N15: 12 | Q15: 12 | T15: =9*18/15 -> 10.8 | W15: 21 | Z15: 7 | AC15: =18*1.1 -> 19.8 | AF15: 17 | AI15: 11 | AL15: 15 | AO15: 10 | AR15: 4 | AU15: 4 | AX15: 15 | BA15: 8 | BD15: 14 | BG15: =13*18/16 -> 14.625 | BJ15: =15*18/17 -> 15.882353 | BM15: 17 | BP15: 17 | BR15: March 4 - DGC Blue | BT15: 10
A16: Luvy | B16: =Details!AP3 -> 12.833333 | C16: =D16*0.75 -> 6 | D16: =(B16-$B$3) -> 8 | E16: =(B15-$B$4)/2 -> 3.6666667 | F16: =(B15-$B$4)*0.6/2 -> 2.2 | H16: 23 | K16: 16 | N16: 14 | Q16: 11 | T16: 12 | W16: 20 | Z16: 10 | AC16: 22 | AF16: 11 | AI16: =8*18/15 -> 9.6 | AL16: 11 | AO16: 11 | AR16: 3 | AU16: 11 | AX16: 19 | BA16: 10 | BD16: 20 | BG16: =13*18/16 -> 14.625 | BJ16: 13 | BM16: =11*18/14 -> 14.142857 | BP16: 14 | BR16: March 1 - DGC Blue | BT16: 15
A17: Rishab | B17: =Details!BE3 -> 13.142857 | C17: =D17*0.75 -> 6.2321429 | D17: =(B17-$B$3) -> 8.3095238 | E17: =(B16-$B$4)/2 -> 3.8333333 | F17: =(B16-$B$4)*0.6/2 -> 2.3 | H17: 13 | K17: 21 | N17: 17 | Q17: 17 | T17: 14 | W17: 15 | Z17: 12 | AC17: 15 | AF17: 17 | AI17: 10 | AL17: 6 | AO17: 12 | AR17: 10 | AU17: 5 | AX17: 20 | BA17: 6 | BD17: 18 | BG17: 16 | BJ17: 11 | BM17: 20 | BP17: 18 | BR17: Feb 26 - DGC Blue | BT17: 13
A18: Sam | B18: =Details!BH3 -> 13.375 | C18: =D18*0.75 -> 6.40625 | D18: =(B18-$B$3) -> 8.5416667 | E18: =(B17-$B$4)/2 -> 3.9880952 | F18: =(B17-$B$4)*0.6/2 -> 2.3928571 | H18: 14 | K18: 17 | N18: 17 | Q18: 15 | T18: 13 | W18: 19 | Z18: 17 | AC18: =12*18/15 -> 14.4 | AF18: =12*1.1 -> 13.2 | AI18: =12*1.2 -> 14.4 | AL18: 16 | AO18: 8 | AR18: 8 | AU18: 6 | AX18: 22 | BA18: 10 | BD18: 19 | BG18: 17 | BJ18: 14 | BM18: 20 | BP18: 13 | BR18: Feb 22 - DGC Blue | BT18: 18
A19: Ashu B'ram | B19: =Details!L3 -> 13.666667 | C19: =D19*0.75 -> 6.625 | D19: =(B19-$B$3) -> 8.8333333 | E19: =(B18-$B$4)/2 -> 4.1041667 | F19: =(B18-$B$4)*0.6/2 -> 2.4625 | H19: =15*1.1 -> 16.5 | K19: 16 | N19: 10 | Q19: 14 | T19: 13 | W19: 19 | Z19: 14 | AC19: 18 | AF19: =13*1.1 -> 14.3 | AI19: 12 | AL19: 8 | AO19: 11 | AR19: 21 | AU19: 6 | AX19: 16 | BA19: 5 | BD19: 10 | BG19: 16 | BJ19: =8*18/14 -> 10.285714 | BM19: 16 | BP19: =15*18/16 -> 16.875 | BR19: 89 on Feb 20 - DLF Blue @ 80% | BT19: 17
A20: Ashu Jain | B20: =Details!O3 -> 14.333333 | C20: =D20*0.75 -> 7.125 | D20: =(B20-$B$3) -> 9.5 | E20: =(#REF!-$B$4)/2 -> #REF! | F20: =(#REF!-$B$4)*0.6/2 -> #REF! | H20: 20 | K20: 15 | N20: 17 | Q20: 18 | T20: 12 | W20: 15 | Z20: 8 | AC20: 16 | AF20: 11 | AI20: 14 | AL20: 13 | AO20: 17 | AR20: 3 | AU20: 8 | AX20: 17 | BA20: 6 | BD20: 12 | BG20: 14 | BJ20: 11 | BM20: 18 | BP20: 17 | BR20: Feb 16 - DGC Blue | BT20: 5
A21: Jaideep | B21: =Details!AD3 -> 14.928571 | C21: =D21*0.75 -> 7.5714286 | D21: =(B21-$B$3) -> 10.095238 | E21: =(B19-$B$4)/2 -> 4.25 | F21: =(B19-$B$4)*0.6/2 -> 2.55 | H21: 7 | K21: 14 | N21: 12 | Q21: 16 | T21: =13*0.8 -> 10.4 | W21: 11 | Z21: 18 | AC21: 10 | AF21: 20 | AI21: 18 | AL21: 15 | AO21: 13 | AR21: 7 | AU21: 5 | AX21: 19 | BA21: 9 | BD21: 18 | BG21: 18 | BJ21: 8 | BM21: 18 | BP21: 10 | BR21: 91 on Feb 12 - JP Yellows @ +10% | BT21: 15
A22: Gaggy | B22: =Details!X3 -> 15.333333 | C22: =D22*0.75 -> 7.875 | D22: =(B22-$B$3) -> 10.5 | E22: =(B20-$B$4)/2 -> 4.5833333 | F22: =(B20-$B$4)*0.6/2 -> 2.75 | H22: 22 | K22: 9 | N22: 7 | Q22: 13 | T22: =20*0.8 -> 16 | W22: 20 | Z22: 15 | AC22: 10 | AF22: 16 | AI22: 8 | AL22: 11 | AO22: 16 | AR22: 6 | AU22: 8 | AX22: 14 | BA22: 10 | BD22: 13 | BG22: 20 | BJ22: 10 | BM22: 6 | BP22: 15 | BR22: Feb 8 - DGC Blue | BT22: 17
A23: Pran | B23: =Details!AY3 -> 15.738095 | C23: =D23*0.75 -> 8.1785714 | D23: =(B23-$B$3) -> 10.904762 | E23: =(B21-$B$4)/2 -> 4.8809524 | F23: =(B21-$B$4)*0.6/2 -> 2.9285714 | H23: 21 | K23: 16 | N23: 13 | Q23: 13 | T23: 12 | W23: 17 | Z23: 15 | AC23: 13 | AF23: 13 | AI23: =13*1.1 -> 14.3 | AL23: 13 | AO23: 15 | AR23: 14 | AU23: 12 | AX23: 16 | BA23: 3 | BD23: 9 | BG23: 16 | BJ23: 11 | BM23: 18 | BP23: 13 | BR23: 87 Feb 6 - ITC Blue @ +10% | BT23: 20
E24: =(B22-$B$4)/2 -> 5.0833333 | F24: =(B22-$B$4)*0.6/2 -> 3.05 | H24: 9 | K24: 14 | N24: 13 | Q24: 14 | T24: =7*18/14 -> 9 | W24: 15 | Z24: =7*18/15 -> 8.4 | AC24: 15 | AF24: 16 | AI24: 5 | AL24: 13 | AO24: 12 | AR24: 6 | AU24: 14 | AX24: 22 | BA24: 6 | BD24: 16 | BG24: 19 | BJ24: 15 | BM24: 13 | BP24: 18 | BR24: 90 on Feb 4 - DLF Blue @ 80% | BT24: =16*0.8 -> 12.8
E25: =(B23-$B$4)/2 -> 5.2857143 | F25: =(B23-$B$4)*0.6/2 -> 3.1714286 | H25: 17 | K25: 13 | N25: 8 | Q25: 15 | T25: 12 | W25: 18 | Z25: =14*18/16 -> 15.75 | AC25: 15 | AF25: 12 | AI25: 13 | AL25: 14 | AO25: 21 | AR25: 6 | AU25: 8 | AX25: 21 | BA25: -3 | BD25: 15 | BG25: 14 | BJ25: =15*18/14 -> 19.285714 | BM25: =12*18/14 -> 15.428571 | BP25: 19 | BT25: 15
H26: 17 | K26: 12 | N26: 12 | Q26: 14 | T26: 15 | W26: 22 | Z26: 14 | AC26: 15 | AF26: 12 | AI26: 10 | AL26: 12 | AO26: 10 | AR26: 11 | AU26: 7 | AX26: 20 | BA26: 8 | BD26: 8 | BG26: 11 | BJ26: 15 | BM26: 16 | BP26: 12 | BT26: 12
H27: 24 | K27: 19 | N27: 15 | Q27: 10 | T27: 15 | W27: 14 | Z27: 11 | AC27: 9 | AF27: =13*18/16 -> 14.625 | AI27: 10 | AL27: 10 | AO27: 12 | AR27: 9 | AU27: 6 | AX27: 19 | BA27: 9 | BD27: 12 | BG27: 16 | BJ27: 14 | BM27: 18 | BP27: 19 | BT27: 13
H28: 18 | K28: 16 | N28: 9 | Q28: 15 | T28: 11 | W28: 16 | Z28: 18 | AC28: =7*18/14 -> 9 | AF28: =12*1.2 -> 14.4 | AI28: 10 | AL28: 13 | AO28: 13 | AR28: 15 | AU28: 10 | AX28: 21 | BA28: 6 | BD28: 15 | BG28: 17 | BJ28: 22 | BM28: 16 | BP28: 14 | BT28: 14
A29: Formula for adjusting scores at non Delhi courses | H29: 17 | K29: =17*1.2 -> 20.4 | N29: 11 | Q29: 12 | T29: 14 | W29: 22 | Z29: 14 | AC29: 12 | AF29: 15 | AI29: 12 | AL29: 15 | AO29: 16 | AR29: 5 | AU29: 13 | AX29: 18 | BA29: 14 | BD29: 11 | BG29: 15 | BJ29: 18 | BM29: 13 | BP29: 22 | BT29: 7
A30: Actual Score | C30: 80 | H30: 18 | K30: =13*1.1 -> 14.3 | N30: 16 | Q30: 21 | T30: 15 | W30: 20 | Z30: 17 | AC30: 15 | AF30: 14 | AI30: 4 | AL30: 20 | AO30: 19 | AR30: 11 | AU30: 6 | AX30: 21 | BA30: 9 | BD30: 14 | BG30: 15 | BJ30: 21 | BM30: 16 | BP30: 12 | BT30: 13
A31: Course Rating | C31: 70.5 | H31: 20 | K31: 16 | N31: 13 | Q31: 12 | T31: 9 | W31: 22 | Z31: 10 | AC31: 19 | AF31: 15 | AI31: 17 | AL31: 13 | AO31: 24 | AR31: 7 | AU31: 4 | AX31: 21 | BA31: 8 | BD31: =12*1.1 -> 13.2 | BG31: 17 | BJ31: 17 | BM31: 18 | BP31: 9 | BT31: =15*1.1 -> 16.5
A32: Slope Rating | C32: 127 | H32: 12 | K32: =18*0.8 -> 14.4 | N32: 12 | Q32: 15 | T32: 8 | W32: =19*1.1 -> 20.9 | Z32: 10 | AC32: 13 | AF32: 17 | AI32: 12 | AL32: 13 | AO32: 22 | AR32: 12 | AU32: 11 | AX32: 24 | BA32: 10 | BD32: 17 | BG32: 14 | BJ32: 11 | BM32: 13 | BP32: =14*1.1 -> 15.4 | BT32: 10
A33: DGC Course Rating | C33: 73.1 | H33: =15*1.1 -> 16.5 | K33: 10 | N33: 11 | Q33: 17 | T33: =16*1.2 -> 19.2 | W33: =21*0.8 -> 16.8 | Z33: 10 | AC33: 10 | AF33: 17 | AI33: 6 | AL33: 6 | AO33: 18 | AR33: 11 | AU33: 8 | AX33: =16*1.1 -> 17.6 | BA33: 11 | BD33: 15 | BG33: 14 | BJ33: 18 | BM33: 15 | BP33: 11 | BT33: 15
A34: DGC Slope Rating | C34: 132 | H34: 13 | K34: =9*18/14 -> 11.571429 | N34: 12 | Q34: 13 | T34: 11 | W34: 19 | Z34: 15 | AC34: 10 | AF34: =13*1.1 -> 14.3 | AI34: 15 | AL34: 10 | AO34: 22 | AR34: 18 | AU34: 3 | AX34: 22 | BA34: 6 | BD34: 15 | BG34: 17 | BJ34: =(7*18/16)*1.1 -> 8.6625 | BM34: 16 | BP34: 15 | BT34: 13
A35: Adjusted Handicap | C35: =((C30-C31)*113/C32+1.1)*C34/113 -> 11.158972 | H35: 15 | K35: 10 | N35: 10 | Q35: 17 | T35: 13 | W35: 13 | Z35: 14 | AC35: 11 | AF35: 18 | AI35: 13 | AL35: 7 | AO35: 15 | AR35: 17 | AU35: 14 | AX35: 20 | BA35: 11 | BD35: 14 | BG35: 17 | BJ35: 16 | BM35: 15 | BP35: 16 | BT35: =13*1.1 -> 14.3
A36: Rounded | C36: =ROUND(C35,0) -> 11 | H36: 19 | K36: 15 | N36: 12 | Q36: 15 | T36: 8 | W36: 20 | Z36: 12 | AC36: 16 | AF36: =10*1.1 -> 11 | AI36: 16 | AL36: 9 | AO36: 13 | AR36: 13 | AU36: 7 | AX36: 21 | BA36: 6 | BD36: 19 | BG36: 22 | BJ36: 19 | BM36: 18 | BP36: 15 | BT36: 14
H37: =15*1.2 -> 18 | K37: 17 | N37: 17 | Q37: 12 | T37: =14*0.8 -> 11.2 | W37: 14 | Z37: 15 | AC37: 7 | AF37: 18 | AI37: 10 | AL37: 9 | AO37: 19 | AR37: 8 | AU37: 9 | AX37: 18 | BA37: 5 | BD37: 11 | BG37: =13*1.1 -> 14.3 | BJ37: 12 | BM37: 17 | BP37: 15 | BT37: =12*1.1 -> 13.2
A38: Adjustments | H38: 17 | K38: 8 | N38: 19 | Q38: 12 | T38: 3 | W38: 16 | Z38: 22 | AC38: 11 | AF38: 17 | AI38: 11 | AL38: 14 | AO38: 16 | AR38: 11 | AU38: 12 | AX38: 20 | BA38: 10 | BD38: 15 | BG38: =17*0.8 -> 13.6 | BJ38: 17 | BM38: 8 | BP38: 13 | BT38: 11
A39: ITC Black tees | C39: @90% | H39: 11 | K39: 18 | N39: 12 | Q39: 14 | T39: 14 | W39: 17 | Z39: 17 | AC39: =14*1.1 -> 15.4 | AF39: 14 | AI39: 13 | AL39: 16 | AO39: 15 | AR39: 16 | AU39: 5 | AX39: 17 | BA39: 9 | BD39: 17 | BG39: 19 | BJ39: 21 | BM39: 14 | BP39: =14*1.1 -> 15.4 | BT39: 13
A40: ITC Yellow tees | C40: +10% or min. 1 stroke | H40: 6 | K40: 12 | N40: 9 | Q40: 20 | T40: =12*1.1 -> 13.2 | W40: 21 | Z40: 16 | AC40: 14 | AF40: 12 | AI40: 14 | AL40: 5 | AO40: 19 | AR40: 12 | AU40: 6 | AX40: 18 | BA40: 6 | BD40: =14*1.1 -> 15.4 | BG40: 21 | BJ40: =15*1.1 -> 16.5 | BM40: 22 | BP40: 15 | BT40: 18
...
