Workbook

Sheet Stroking
A1: Player | B1: Handicap | C1: Strokes
A2: =Details!G1 -> Tav | B2: =+Details!I3 -> 1.5 | C2: =(B2-$B$2)*0.75 -> 0
A3: =Details!A1 -> Poky | B3: =+Details!C3 -> 4.8333333 | C3: =(B3-$B$2)*0.75 -> 2.5
A4: =Details!AE1 -> Raul | B4: =Details!AG3 -> 5.1666667 | C4: =(B4-$B$2)*0.75 -> 2.75
A5: =Details!D1 -> Nutty | B5: =Details!F3 -> 5.1666667 | C5: =(B5-$B$2)*0.75 -> 2.75
A6: =Details!AB1 -> Chauds | B6: =Details!AD3 -> 7.5 | C6: =(B6-$B$2)*0.75 -> 4.5
A7: =Details!V1 -> AC | B7: =+Details!X3 -> 8.1666667 | C7: =(B7-$B$2)*0.75 -> 5
A8: =Details!AZ1 -> DP | B8: =Details!BB3 -> 11 | C8: =(B8-$B$2)*0.75 -> 7.125
A9: =Details!AN1 -> JV | B9: =Details!AP3 -> 11.666667 | C9: =(B9-$B$2)*0.75 -> 7.625
A10: =Details!AH1 -> Atul | B10: =Details!AJ3 -> 12.283333 | C10: =(B10-$B$2)*0.75 -> 8.0875
A11: =Details!J1 -> Kartik | B11: =Details!L3 -> 12.333333 | C11: =(B11-$B$2)*0.75 -> 8.125
A12: =Details!AT1 -> Bharat | B12: =Details!AV3 -> 12.5 | C12: =(B12-$B$2)*0.75 -> 8.25
A13: =Details!AQ1 -> Luvy | B13: =Details!AS3 -> 12.833333 | C13: =(B13-$B$2)*0.75 -> 8.5
A14: =Details!P1 -> Boozy | B14: =Details!R3 -> 13.066667 | C14: =(B14-$B$2)*0.75 -> 8.675
A15: =Details!M1 -> Ashu | B15: =+Details!O3 -> 13.666667 | C15: =(B15-$B$2)*0.75 -> 9.125
A16: =Details!BC1 -> Ashu J | B16: =Details!BE3 -> 14.333333 | C16: =(B16-$B$2)*0.75 -> 9.625
A17: =Details!BF1 -> Gargi | B17: =Details!BH3 -> 14.833333 | C17: =(B17-$B$2)*0.75 -> 10 | F17: `
A18: =Details!AK1 -> Tarun | B18: =Details!AM3 -> 14.933333 | C18: =(B18-$B$2)*0.75 -> 10.075
A19: =+Details!S1 -> PK | B19: =Details!U3 -> 15 | C19: =(B19-$B$2)*0.75 -> 10.125
A20: =Details!Y1 -> Gags | B20: =Details!AA3 -> 15.333333 | C20: =(B20-$B$2)*0.75 -> 10.375
A24: Order Of Merit | B24: Money
A25: =Details!V1 -> AC | B25: =+Details!V3 -> 17900
A26: =Details!G1 -> Tav | B26: =+Details!G3 -> 12900
A27: =Details!J1 -> Kartik | B27: =Details!J3 -> 10400
A28: =Details!AE1 -> Raul | B28: =Details!AE3 -> 8500
A29: =Details!M1 -> Ashu | B29: =Details!M3 -> 6000
A30: =+Details!S1 -> PK | B30: =+Details!S3 -> 4900
A31: JV | B31: =Details!AN3 -> 4510
A32: =Details!AH1 -> Atul | B32: =Details!AH3 -> 2100
A33: =Details!A1 -> Poky | B33: =+Details!A3 -> 0
A34: =Details!AK1 -> Tarun | B34: =Details!AK3 -> -580
A35: =Details!AQ1 -> Luvy | B35: =Details!AQ3 -> -1500
A36: =Details!AB1 -> Chauds | B36: =Details!AB3 -> -2100
A37: =Details!AT1 -> Bharat | B37: =Details!AT3 -> -2300
A38: =Details!BF1 -> Gargi | B38: =Details!BF3 -> -3300
A39: =Details!BC1 -> Ashu J | B39: =Details!BC3 -> -4350
A40: =Details!D1 -> Nutty | B40: =+Details!D3 -> -5050
A41: =Details!Y1 -> Gags | B41: =Details!Y3 -> -5530
A42: DP | B42: =Details!AZ3 -> -13400
A43: =Details!P1 -> Boozy | B43: =Details!P3 -> -24700
...

Sheet Details
A1: Poky | D1: Nutty | G1: Tav | J1: Kartik | M1: Ashu | P1: Boozy | S1: PK | V1: AC | Y1: Gags | AB1: Chauds | AE1: Raul | AH1: Atul | AK1: Tarun | AN1: JV | AQ1: Luvy | AT1: Bharat | AW1: Bery | AZ1: DP | BC1: Ashu J | BF1: Gargi
A2: Money | B2: Score | C2: Ave | D2: Money | E2: Score | F2: Ave | G2: Money | H2: Score | I2: Ave | J2: Money | K2: Score | L2: Ave | M2: Money | N2: Score | O2: Ave | P2: Money | Q2: Score | R2: Ave | S2: Money | T2: Score | U2: Ave | V2: Money | W2: Score | X2: Ave | Y2: Money | Z2: Score | AA2: Ave | AB2: Money | AC2: Score | AD2: Ave | AE2: Money | AF2: Score | AG2: Ave | AH2: Money | AI2: Score | AJ2: Ave | AK2: Money | AL2: Score | AM2: Ave | AN2: Money | AO2: Score | AP2: Ave | AQ2: Money | AR2: Score | AS2: Ave | AT2: Money | AU2: Score | AV2: Ave | AW2: Money | AX2: Score | AY2: Ave | AZ2: Money | BA2: Score | BB2: Ave | BC2: Money | BD2: Score | BE2: Ave | BF2: Money | BG2: Score | BH2: Ave
A3: =SUM(A4:A200) -> 0 | C3: =C5 -> 4.8333333 | D3: =SUM(D4:D200) -> -5050 | F3: =F5 -> 5.1666667 | G3: =SUM(G4:G200) -> 12900 | I3: =I5 -> 1.5 | J3: =SUM(J4:J200) -> 10400 | L3: =L5 -> 12.333333 | M3: =SUM(M4:M200) -> 6000 | O3: =O5 -> 13.666667 | P3: =SUM(P4:P200) -> -24700 | R3: =R5 -> 13.066667 | S3: =SUM(S4:S200) -> 4900 | U3: =U5 -> 15 | V3: =SUM(V4:V200) -> 17900 | X3: =X5 -> 8.1666667 | Y3: =SUM(Y4:Y200) -> -5530 | AA3: =AA5 -> 15.333333 | AB3: =SUM(AB4:AB200) -> -2100 | AD3: =AD5 -> 7.5 | AE3: =SUM(AE4:AE200) -> 8500 | AG3: =AG5 -> 5.1666667 | AH3: =SUM(AH4:AH200) -> 2100 | AJ3: =AJ5 -> 12.283333 | AK3: =SUM(AK4:AK200) -> -580 | AM3: =AM5 -> 14.933333 | AN3: =SUM(AN4:AN200) -> 4510 | AP3: =AP5 -> 11.666667 | AQ3: =SUM(AQ4:AQ200) -> -1500 | AS3: =AS5 -> 12.833333 | AT3: =SUM(AT4:AT200) -> -2300 | AV3: =AV5 -> 12.5 | AW3: =SUM(AW4:AW16) -> -200 | AY3: =AY5 -> 0 | AZ3: =SUM(AZ4:AZ200) -> -13400 | BB3: =BB5 -> 11 | BC3: =SUM(BC4:BC200) -> -4350 | BE3: =BE5 -> 14.333333 | BF3: =SUM(BF4:BF200) -> -3300 | BH3: =BH5 -> 14.833333
B5: 3 | C5: =SUM(SMALL(B5:B16,{1,2,3,4,5,6}))/6 -> 4.8333333 | E5: 6 | F5: =SUM(SMALL(E5:E16,{1,2,3,4,5,6}))/6 -> 5.1666667 | H5: 3 | I5: =SUM(SMALL(H5:H16,{1,2,3,4,5,6}))/6 -> 1.5 | K5: 16 | L5: =SUM(SMALL(K5:K16,{1,2,3,4,5,6}))/6 -> 12.333333 | N5: 24 | O5: =SUM(SMALL(N5:N16,{1,2,3,4,5,6}))/6 -> 13.666667 | P5: -2000 | Q5: 17 | R5: =SUM(SMALL(Q5:Q16,{1,2,3,4,5,6}))/6 -> 13.066667 | S5: -1000 | T5: 18 | U5: =SUM(SMALL(T5:T16,{1,2,3,4,5,6}))/6 -> 15 | W5: 21 | X5: =SUM(SMALL(W5:W16,{1,2,3,4,5,6}))/6 -> 8.1666667 | Z5: 24 | AA5: =SUM(SMALL(Z5:Z16,{1,2,3,4,5,6}))/6 -> 15.333333 | AC5: 13 | AD5: =SUM(SMALL(AC5:AC16,{1,2,3,4,5,6}))/6 -> 7.5 | AF5: 4 | AG5: =SUM(SMALL(AF5:AF16,{1,2,3,4,5,6}))/6 -> 5.1666667 | AH5: 600 | AI5: 15 | AJ5: =SUM(SMALL(AI5:AI16,{1,2,3,4,5,6}))/6 -> 12.283333 | AK5: -900 | AL5: 17 | AM5: =SUM(SMALL(AL5:AL16,{1,2,3,4,5,6}))/6 -> 14.933333 | AN5: 2000 | AO5: 14 | AP5: =SUM(SMALL(AO5:AO16,{1,2,3,4,5,6}))/6 -> 11.666667 | AR5: 18 | AS5: =SUM(SMALL(AR5:AR16,{1,2,3,4,5,6}))/6 -> 12.833333 | AU5: 14 | AV5: =SUM(SMALL(AU5:AU16,{1,2,3,4,5,6}))/6 -> 12.5 | AZ5: 900 | BA5: 13 | BB5: =SUM(SMALL(BA5:BA16,{1,2,3,4,5,6}))/6 -> 11 | BD5: 16 | BE5: =SUM(SMALL(BD5:BD16,{1,2,3,4,5,6}))/6 -> 14.333333 | BF5: 900 | BG5: 22 | BH5: =SUM(SMALL(BG5:BG16,{1,2,3,4,5,6}))/6 -> 14.833333
B6: 8 | C6: =SUM(SMALL(B6:B17,{1,2,3,4,5,6}))/6 -> 5.1666667 | D6: 600 | E6: 6 | F6: =SUM(SMALL(E6:E17,{1,2,3,4,5,6}))/6 -> 5.5 | G6: -600 | H6: 3 | I6: =SUM(SMALL(H6:H17,{1,2,3,4,5,6}))/6 -> 1.3333333 | K6: 16 | L6: =SUM(SMALL(K6:K17,{1,2,3,4,5,6}))/6 -> 11 | N6: 9 | O6: =SUM(SMALL(N6:N17,{1,2,3,4,5,6}))/6 -> 13.666667 | Q6: 15 | R6: =SUM(SMALL(Q6:Q17,{1,2,3,4,5,6}))/6 -> 12.233333 | T6: 15 | U6: =SUM(SMALL(T6:T17,{1,2,3,4,5,6}))/6 -> 15 | W6: 12 | X6: =SUM(SMALL(W6:W17,{1,2,3,4,5,6}))/6 -> 8.1666667 | Z6: 19 | AA6: =SUM(SMALL(Z6:Z17,{1,2,3,4,5,6}))/6 -> 14.666667 | AC6: 17 | AD6: =SUM(SMALL(AC6:AC17,{1,2,3,4,5,6}))/6 -> 7.5 | AE6: -900 | AF6: 12 | AG6: =SUM(SMALL(AF6:AF17,{1,2,3,4,5,6}))/6 -> 5.5 | AH6: 3000 | AI6: 15 | AJ6: =SUM(SMALL(AI6:AI17,{1,2,3,4,5,6}))/6 -> 12.283333 | AL6: 14 | AM6: =SUM(SMALL(AL6:AL17,{1,2,3,4,5,6}))/6 -> 13.6 | AO6: 13 | AP6: =SUM(SMALL(AO6:AO17,{1,2,3,4,5,6}))/6 -> 11.666667 | AR6: 20 | AS6: =SUM(SMALL(AR6:AR17,{1,2,3,4,5,6}))/6 -> 12.333333 | AU6: 18 | AV6: =SUM(SMALL(AU6:AU17,{1,2,3,4,5,6}))/6 -> 12.833333 | AZ6: -600 | BA6: 15 | BB6: =SUM(SMALL(BA6:BA17,{1,2,3,4,5,6}))/6 -> 11 | BC6: 2000 | BD6: 14 | BE6: =SUM(SMALL(BD6:BD17,{1,2,3,4,5,6}))/6 -> 14.333333 | BG6: 15 | BH6: =SUM(SMALL(BG6:BG17,{1,2,3,4,5,6}))/6 -> 14.5
B7: 15 | C7: =SUM(SMALL(B7:B18,{1,2,3,4,5,6}))/6 -> 5 | E7: 9 | F7: =SUM(SMALL(E7:E18,{1,2,3,4,5,6}))/6 -> 5.8333333 | H7: 4 | I7: =SUM(SMALL(H7:H18,{1,2,3,4,5,6}))/6 -> 1.5 | K7: 17 | L7: =SUM(SMALL(K7:K18,{1,2,3,4,5,6}))/6 -> 11 | N7: 15 | O7: =SUM(SMALL(N7:N18,{1,2,3,4,5,6}))/6 -> 15 | P7: -2700 | Q7: 18 | R7: =SUM(SMALL(Q7:Q18,{1,2,3,4,5,6}))/6 -> 10.9 | S7: 0 | T7: 18 | U7: =SUM(SMALL(T7:T18,{1,2,3,4,5,6}))/6 -> 15.333333 | W7: 18 | X7: =SUM(SMALL(W7:W18,{1,2,3,4,5,6}))/6 -> 8.1666667 | Z7: 21 | AA7: =SUM(SMALL(Z7:Z18,{1,2,3,4,5,6}))/6 -> 14.666667 | AC7: 9 | AD7: =SUM(SMALL(AC7:AC18,{1,2,3,4,5,6}))/6 -> 7.5 | AF7: 5 | AG7: =SUM(SMALL(AF7:AF18,{1,2,3,4,5,6}))/6 -> 5.5 | AI7: =17*0.8 -> 13.6 | AJ7: =SUM(SMALL(AI7:AI18,{1,2,3,4,5,6}))/6 -> 12.283333 | AL7: 17 | AM7: =SUM(SMALL(AL7:AL18,{1,2,3,4,5,6}))/6 -> 12.866667 | AO7: 13 | AP7: =SUM(SMALL(AO7:AO18,{1,2,3,4,5,6}))/6 -> 11.7 | AQ7: -1800 | AR7: 19 | AS7: =SUM(SMALL(AR7:AR18,{1,2,3,4,5,6}))/6 -> 11.166667 | AU7: 16 | AV7: =SUM(SMALL(AU7:AU18,{1,2,3,4,5,6}))/6 -> 12.666667 | BA7: 10 | BB7: =SUM(SMALL(BA7:BA18,{1,2,3,4,5,6}))/6 -> 10.5 | BD7: 20 | BE7: =SUM(SMALL(BD7:BD18,{1,2,3,4,5,6}))/6 -> 14.833333 | BG7: 17 | BH7: =SUM(SMALL(BG7:BG18,{1,2,3,4,5,6}))/6 -> 13.5
A8: -3000 | B8: 10 | C8: =SUM(SMALL(B8:B19,{1,2,3,4,5,6}))/6 -> 5 | D8: -3000 | E8: 9 | F8: =SUM(SMALL(E8:E19,{1,2,3,4,5,6}))/6 -> 5.8333333 | H8: 0 | I8: =SUM(SMALL(H8:H19,{1,2,3,4,5,6}))/6 -> 1.5 | J8: -300 | K8: 15 | L8: =SUM(SMALL(K8:K19,{1,2,3,4,5,6}))/6 -> 10.166667 | N8: 14 | O8: =SUM(SMALL(N8:N19,{1,2,3,4,5,6}))/6 -> 15.166667 | P8: -3300 | Q8: =14*1.1 -> 15.4 | R8: =SUM(SMALL(Q8:Q19,{1,2,3,4,5,6}))/6 -> 9.8333333 | S8: 0 | T8: 13 | U8: =SUM(SMALL(T8:T19,{1,2,3,4,5,6}))/6 -> 14.833333 | W8: 12 | X8: =SUM(SMALL(W8:W19,{1,2,3,4,5,6}))/6 -> 8.1666667 | Y8: 3600 | Z8: 19 | AA8: =SUM(SMALL(Z8:Z19,{1,2,3,4,5,6}))/6 -> 14.666667 | AC8: 12 | AD8: =SUM(SMALL(AC8:AC19,{1,2,3,4,5,6}))/6 -> 7.6666667 | AF8: 7 | AG8: =SUM(SMALL(AF8:AF19,{1,2,3,4,5,6}))/6 -> 5.5 | AI8: 17 | AJ8: =SUM(SMALL(AI8:AI19,{1,2,3,4,5,6}))/6 -> 11.683333 | AL8: 18 | AM8: =SUM(SMALL(AL8:AL19,{1,2,3,4,5,6}))/6 -> 12.2 | AO8: 12 | AP8: =SUM(SMALL(AO8:AO19,{1,2,3,4,5,6}))/6 -> 11.916667 | AR8: 17 | AS8: =SUM(SMALL(AR8:AR19,{1,2,3,4,5,6}))/6 -> 10.666667 | AU8: 14 | AV8: =SUM(SMALL(AU8:AU19,{1,2,3,4,5,6}))/6 -> 12.5 | BA8: 8 | BB8: =SUM(SMALL(BA8:BA19,{1,2,3,4,5,6}))/6 -> 10.5 | BD8: 15 | BE8: =SUM(SMALL(BD8:BD19,{1,2,3,4,5,6}))/6 -> 13.666667 | BG8: 21 | BH8: =SUM(SMALL(BG8:BG19,{1,2,3,4,5,6}))/6 -> 13.166667
A9: -300 | B9: 8 | C9: =SUM(SMALL(B9:B20,{1,2,3,4,5,6}))/6 -> 5 | E9: 8 | F9: =SUM(SMALL(E9:E20,{1,2,3,4,5,6}))/6 -> 5 | H9: 2 | I9: =SUM(SMALL(H9:H20,{1,2,3,4,5,6}))/6 -> 2 | J9: -3600 | K9: 24 | L9: =SUM(SMALL(K9:K20,{1,2,3,4,5,6}))/6 -> 10.166667 | N9: 20 | O9: =SUM(SMALL(N9:N20,{1,2,3,4,5,6}))/6 -> 15.333333 | Q9: 21 | R9: =SUM(SMALL(Q9:Q20,{1,2,3,4,5,6}))/6 -> 9.1666667 | S9: -1500 | T9: 17 | U9: =SUM(SMALL(T9:T20,{1,2,3,4,5,6}))/6 -> 15.166667 | W9: 10 | X9: =SUM(SMALL(W9:W20,{1,2,3,4,5,6}))/6 -> 8.1666667 | Y9: 150 | Z9: 18 | AA9: =SUM(SMALL(Z9:Z20,{1,2,3,4,5,6}))/6 -> 14.166667 | AC9: 12 | AD9: =SUM(SMALL(AC9:AC20,{1,2,3,4,5,6}))/6 -> 7.6666667 | AF9: 5 | AG9: =SUM(SMALL(AF9:AF20,{1,2,3,4,5,6}))/6 -> 5.3333333 | AI9: 12 | AJ9: =SUM(SMALL(AI9:AI20,{1,2,3,4,5,6}))/6 -> 11.516667 | AL9: 15 | AM9: =SUM(SMALL(AL9:AL20,{1,2,3,4,5,6}))/6 -> 12.2 | AN9: -2000 | AO9: 16 | AP9: =SUM(SMALL(AO9:AO20,{1,2,3,4,5,6}))/6 -> 11.75 | AQ9: -800 | AR9: 12 | AS9: =SUM(SMALL(AR9:AR20,{1,2,3,4,5,6}))/6 -> 10.666667 | AU9: 16 | AV9: =SUM(SMALL(AU9:AU20,{1,2,3,4,5,6}))/6 -> 12.666667 | BA9: 11 | BB9: =SUM(SMALL(BA9:BA20,{1,2,3,4,5,6}))/6 -> 11.333333 | BD9: 15 | BE9: =SUM(SMALL(BD9:BD20,{1,2,3,4,5,6}))/6 -> 14 | BG9: 19 | BH9: =SUM(SMALL(BG9:BG20,{1,2,3,4,5,6}))/6 -> 13.166667
A10: -600 | B10: 7 | C10: =SUM(SMALL(B10:B21,{1,2,3,4,5,6}))/6 -> 4.8333333 | D10: 300 | E10: =13*0.8 -> 10.4 | F10: =SUM(SMALL(E10:E21,{1,2,3,4,5,6}))/6 -> 4.8333333 | G10: 3600 | H10: 3 | I10: =SUM(SMALL(H10:H21,{1,2,3,4,5,6}))/6 -> 2.3333333 | J10: 600 | K10: 12 | L10: =SUM(SMALL(K10:K21,{1,2,3,4,5,6}))/6 -> 10.166667 | M10: 1800 | N10: 17 | O10: =SUM(SMALL(N10:N21,{1,2,3,4,5,6}))/6 -> 14.833333 | Q10: 18 | R10: =SUM(SMALL(Q10:Q21,{1,2,3,4,5,6}))/6 -> 8.8333333 | T10: 23 | U10: =SUM(SMALL(T10:T21,{1,2,3,4,5,6}))/6 -> 15.166667 | W10: 14 | X10: =SUM(SMALL(W10:W21,{1,2,3,4,5,6}))/6 -> 8.5 | Y10: -2700 | Z10: 13 | AA10: =SUM(SMALL(Z10:Z21,{1,2,3,4,5,6}))/6 -> 13.333333 | AC10: 10 | AD10: =SUM(SMALL(AC10:AC21,{1,2,3,4,5,6}))/6 -> 7.5 | AF10: 8 | AG10: =SUM(SMALL(AF10:AF21,{1,2,3,4,5,6}))/6 -> 5.8333333 | AI10: 19 | AJ10: =SUM(SMALL(AI10:AI21,{1,2,3,4,5,6}))/6 -> 11.35 | AL10: 18 | AM10: =SUM(SMALL(AL10:AL21,{1,2,3,4,5,6}))/6 -> 12.2 | AO10: 16 | AP10: =SUM(SMALL(AO10:AO21,{1,2,3,4,5,6}))/6 -> 11.75 | AR10: 15 | AS10: =SUM(SMALL(AR10:AR21,{1,2,3,4,5,6}))/6 -> 10.833333 | AU10: 20 | AV10: =SUM(SMALL(AU10:AU21,{1,2,3,4,5,6}))/6 -> 12.666667 | BA10: 14 | BB10: =SUM(SMALL(BA10:BA21,{1,2,3,4,5,6}))/6 -> 10.666667 | BD10: 23 | BE10: =SUM(SMALL(BD10:BD21,{1,2,3,4,5,6}))/6 -> 13.5 | BG10: 22 | BH10: =SUM(SMALL(BG10:BG21,{1,2,3,4,5,6}))/6 -> 13.166667
A11: -3600 | B11: 6 | C11: =SUM(SMALL(B11:B22,{1,2,3,4,5,6}))/6 -> 4.8333333 | D11: 600 | E11: 6 | F11: =SUM(SMALL(E11:E22,{1,2,3,4,5,6}))/6 -> 4.6666667 | G11: 2700 | H11: -2 | I11: =SUM(SMALL(H11:H22,{1,2,3,4,5,6}))/6 -> 2.3333333 | K11: 13 | L11: =SUM(SMALL(K11:K22,{1,2,3,4,5,6}))/6 -> 10 | N11: 17 | O11: =SUM(SMALL(N11:N22,{1,2,3,4,5,6}))/6 -> 13.666667 | P11: -3000 | Q11: 20 | R11: =SUM(SMALL(Q11:Q22,{1,2,3,4,5,6}))/6 -> 8.8333333 | S11: -2000 | T11: 19 | U11: =SUM(SMALL(T11:T22,{1,2,3,4,5,6}))/6 -> 15.166667 | W11: 5 | X11: =SUM(SMALL(W11:W22,{1,2,3,4,5,6}))/6 -> 8.5 | Y11: -1000 | Z11: 16 | AA11: =SUM(SMALL(Z11:Z22,{1,2,3,4,5,6}))/6 -> 13.833333 | AC11: 6 | AD11: =SUM(SMALL(AC11:AC22,{1,2,3,4,5,6}))/6 -> 7.5 | AF11: 7 | AG11: =SUM(SMALL(AF11:AF22,{1,2,3,4,5,6}))/6 -> 5.8333333 | AI11: 13 | AJ11: =SUM(SMALL(AI11:AI22,{1,2,3,4,5,6}))/6 -> 11.35 | AL11: 15 | AM11: =SUM(SMALL(AL11:AL22,{1,2,3,4,5,6}))/6 -> 12.2 | AN11: 1000 | AO11: 18 | AP11: =SUM(SMALL(AO11:AO22,{1,2,3,4,5,6}))/6 -> 11.75 | AQ11: -2000 | AR11: 16 | AS11: =SUM(SMALL(AR11:AR22,{1,2,3,4,5,6}))/6 -> 10.833333 | AU11: 16 | AV11: =SUM(SMALL(AU11:AU22,{1,2,3,4,5,6}))/6 -> 12.333333 | AZ11: -2700 | BA11: 14 | BB11: =SUM(SMALL(BA11:BA22,{1,2,3,4,5,6}))/6 -> 10.666667 | BD11: 22 | BE11: =SUM(SMALL(BD11:BD22,{1,2,3,4,5,6}))/6 -> 11.833333 | BG11: 16 | BH11: =SUM(SMALL(BG11:BG22,{1,2,3,4,5,6}))/6 -> 13.166667
B12: 4 | C12: =SUM(SMALL(B12:B23,{1,2,3,4,5,6}))/6 -> 4.8333333 | E12: 6 | F12: =SUM(SMALL(E12:E23,{1,2,3,4,5,6}))/6 -> 4.8333333 | H12: 9 | I12: =SUM(SMALL(H12:H23,{1,2,3,4,5,6}))/6 -> 3.5 | K12: 14 | L12: =SUM(SMALL(K12:K23,{1,2,3,4,5,6}))/6 -> 10 | M12: -2700 | N12: 14 | O12: =SUM(SMALL(N12:N23,{1,2,3,4,5,6}))/6 -> 13.666667 | P12: -4000 | Q12: 19 | R12: =SUM(SMALL(Q12:Q23,{1,2,3,4,5,6}))/6 -> 8.8333333 | S12: 1600 | T12: 14 | U12: =SUM(SMALL(T12:T23,{1,2,3,4,5,6}))/6 -> 14.466667 | V12: 2700 | W12: 7 | X12: =SUM(SMALL(W12:W23,{1,2,3,4,5,6}))/6 -> 9.6666667 | Z12: 10 | AA12: =SUM(SMALL(Z12:Z23,{1,2,3,4,5,6}))/6 -> 14 | AC12: 5 | AD12: =SUM(SMALL(AC12:AC23,{1,2,3,4,5,6}))/6 -> 8.1666667 | AF12: 3 | AG12: =SUM(SMALL(AF12:AF23,{1,2,3,4,5,6}))/6 -> 5.1666667 | AI12: 16 | AJ12: =SUM(SMALL(AI12:AI23,{1,2,3,4,5,6}))/6 -> 11.35 | AL12: 15 | AM12: =SUM(SMALL(AL12:AL23,{1,2,3,4,5,6}))/6 -> 12.366667 | AO12: 13 | AP12: =SUM(SMALL(AO12:AO23,{1,2,3,4,5,6}))/6 -> 11.533333 | AR12: 15 | AS12: =SUM(SMALL(AR12:AR23,{1,2,3,4,5,6}))/6 -> 10.833333 | AU12: 15 | AV12: =SUM(SMALL(AU12:AU23,{1,2,3,4,5,6}))/6 -> 12 | BA12: 17 | BB12: =SUM(SMALL(BA12:BA23,{1,2,3,4,5,6}))/6 -> 10 | BD12: 16 | BE12: =SUM(SMALL(BD12:BD23,{1,2,3,4,5,6}))/6 -> 11.333333 | BG12: 14 | BH12: 13.166667
B13: 7 | C13: =SUM(SMALL(B13:B24,{1,2,3,4,5,6}))/6 -> 5.1666667 | D13: -750 | E13: 13 | F13: =SUM(SMALL(E13:E24,{1,2,3,4,5,6}))/6 -> 4.8333333 | H13: 6 | I13: =SUM(SMALL(H13:H24,{1,2,3,4,5,6}))/6 -> 3.5 | K13: 12 | L13: =SUM(SMALL(K13:K24,{1,2,3,4,5,6}))/6 -> 10 | N13: 24 | O13: =SUM(SMALL(N13:N24,{1,2,3,4,5,6}))/6 -> 13.666667 | Q13: 9 | R13: =SUM(SMALL(Q13:Q24,{1,2,3,4,5,6}))/6 -> 8.8333333 | S13: -4000 | T13: 18 | U13: =SUM(SMALL(T13:T24,{1,2,3,4,5,6}))/6 -> 14.633333 | W13: 10 | X13: =SUM(SMALL(W13:W24,{1,2,3,4,5,6}))/6 -> 10.166667 | Z13: 22 | AA13: =SUM(SMALL(Z13:Z24,{1,2,3,4,5,6}))/6 -> 14.833333 | AB13: 600 | AC13: 7 | AD13: =SUM(SMALL(AC13:AC24,{1,2,3,4,5,6}))/6 -> 9 | AF13: 15 | AG13: =SUM(SMALL(AF13:AF24,{1,2,3,4,5,6}))/6 -> 5.6666667 | AI13: 20 | AJ13: =SUM(SMALL(AI13:AI24,{1,2,3,4,5,6}))/6 -> 11.166667 | AL13: 17 | AM13: =SUM(SMALL(AL13:AL24,{1,2,3,4,5,6}))/6 -> 12.2 | AN13: -240 | AO13: 18 | AP13: =SUM(SMALL(AO13:AO24,{1,2,3,4,5,6}))/6 -> 11.75 | AQ13: -2000 | AR13: 14 | AS13: =SUM(SMALL(AR13:AR24,{1,2,3,4,5,6}))/6 -> 10.666667 | AU13: 9 | AV13: =SUM(SMALL(AU13:AU24,{1,2,3,4,5,6}))/6 -> 12 | BA13: 13 | BB13: =SUM(SMALL(BA13:BA24,{1,2,3,4,5,6}))/6 -> 9.3 | BD13: 18 | BE13: =SUM(SMALL(BD13:BD24,{1,2,3,4,5,6}))/6 -> 11.166667 | BG13: 14 | BH13: 13
A14: -3000 | B14: 5 | C14: =SUM(SMALL(B14:B25,{1,2,3,4,5,6}))/6 -> 5.1666667 | E14: 17 | F14: =SUM(SMALL(E14:E25,{1,2,3,4,5,6}))/6 -> 4.6666667 | G14: -3300 | H14: 9 | I14: =SUM(SMALL(H14:H25,{1,2,3,4,5,6}))/6 -> 2.8333333 | K14: 12 | L14: =SUM(SMALL(K14:K25,{1,2,3,4,5,6}))/6 -> 10.166667 | N14: 14 | O14: =SUM(SMALL(N14:N25,{1,2,3,4,5,6}))/6 -> 13.166667 | Q14: 8 | R14: =SUM(SMALL(Q14:Q25,{1,2,3,4,5,6}))/6 -> 9.1666667 | T14: 13 | U14: =SUM(SMALL(T14:T25,{1,2,3,4,5,6}))/6 -> 13.466667 | V14: 3300 | W14: 7 | X14: =SUM(SMALL(W14:W25,{1,2,3,4,5,6}))/6 -> 10.5 | Z14: 16 | AA14: =SUM(SMALL(Z14:Z25,{1,2,3,4,5,6}))/6 -> 14.833333 | AB14: 1500 | AC14: 8 | AD14: =SUM(SMALL(AC14:AC25,{1,2,3,4,5,6}))/6 -> 10 | AF14: 12 | AG14: =SUM(SMALL(AF14:AF25,{1,2,3,4,5,6}))/6 -> 3.8333333 | AH14: 3300 | AI14: =11*1.1 -> 12.1 | AJ14: =SUM(SMALL(AI14:AI25,{1,2,3,4,5,6}))/6 -> 11.166667 | AL14: 20 | AM14: =SUM(SMALL(AL14:AL25,{1,2,3,4,5,6}))/6 -> 11.366667 | AN14: 2100 | AO14: 8 | AP14: =SUM(SMALL(AO14:AO25,{1,2,3,4,5,6}))/6 -> 11.366667 | AR14: 16 | AS14: =SUM(SMALL(AR14:AR25,{1,2,3,4,5,6}))/6 -> 10.666667 | AU14: 18 | AV14: =SUM(SMALL(AU14:AU25,{1,2,3,4,5,6}))/6 -> 12.833333 | BA14: 19 | BB14: =SUM(SMALL(BA14:BA25,{1,2,3,4,5,6}))/6 -> 8.9333333 | BD14: 18 | BE14: =SUM(SMALL(BD14:BD25,{1,2,3,4,5,6}))/6 -> 10.333333 | BF14: 2400 | BG14: 15 | BH14: 13.166667
A15: 600 | B15: 4 | C15: =SUM(SMALL(B15:B26,{1,2,3,4,5,6}))/6 -> 5.5 | D15: 3000 | E15: 4 | F15: =SUM(SMALL(E15:E26,{1,2,3,4,5,6}))/6 -> 4.6666667 | G15: -2700 | H15: 7 | I15: =SUM(SMALL(H15:H26,{1,2,3,4,5,6}))/6 -> 2.8333333 | K15: 15 | L15: =SUM(SMALL(K15:K26,{1,2,3,4,5,6}))/6 -> 10.166667 | N15: 20 | O15: =SUM(SMALL(N15:N26,{1,2,3,4,5,6}))/6 -> 12.833333 | Q15: 21 | R15: =SUM(SMALL(Q15:Q26,{1,2,3,4,5,6}))/6 -> 9.1666667 | T15: 24 | U15: =SUM(SMALL(T15:T26,{1,2,3,4,5,6}))/6 -> 13.8 | V15: 2700 | W15: 10 | X15: =SUM(SMALL(W15:W26,{1,2,3,4,5,6}))/6 -> 10.666667 | Y15: -4000 | Z15: 21 | AA15: =SUM(SMALL(Z15:Z26,{1,2,3,4,5,6}))/6 -> 15.166667 | AB15: -2000 | AC15: 20 | AD15: =SUM(SMALL(AC15:AC26,{1,2,3,4,5,6}))/6 -> 9.6666667 | AF15: 8 | AG15: =SUM(SMALL(AF15:AF26,{1,2,3,4,5,6}))/6 -> 3.8333333 | AI15: 11 | AJ15: =SUM(SMALL(AI15:AI26,{1,2,3,4,5,6}))/6 -> 11.166667 | AL15: 21 | AM15: =SUM(SMALL(AL15:AL26,{1,2,3,4,5,6}))/6 -> 11.366667 | AN15: -600 | AO15: 17 | AP15: =SUM(SMALL(AO15:AO26,{1,2,3,4,5,6}))/6 -> 12.033333 | AR15: 10 | AS15: =SUM(SMALL(AR15:AR26,{1,2,3,4,5,6}))/6 -> 10.333333 | AU15: 12 | AV15: =SUM(SMALL(AU15:AU26,{1,2,3,4,5,6}))/6 -> 12.833333 | AZ15: -2000 | BA15: 20 | BB15: =SUM(SMALL(BA15:BA26,{1,2,3,4,5,6}))/6 -> 8.4333333 | BC15: 600 | BD15: 12 | BE15: =SUM(SMALL(BD15:BD26,{1,2,3,4,5,6}))/6 -> 10.166667 | BF15: 1500 | BG15: 15 | BH15: 12.533333
A16: -1800 | B16: 11 | C16: =SUM(SMALL(B16:B27,{1,2,3,4,5,6}))/6 -> 5.8333333 | D16: -600 | E16: 3 | F16: =SUM(SMALL(E16:E27,{1,2,3,4,5,6}))/6 -> 5.1666667 | H16: 4 | I16: =SUM(SMALL(H16:H27,{1,2,3,4,5,6}))/6 -> 2.6666667 | K16: 11 | L16: =SUM(SMALL(K16:K27,{1,2,3,4,5,6}))/6 -> 9.6666667 | N16: 16 | O16: =SUM(SMALL(N16:N27,{1,2,3,4,5,6}))/6 -> 12.833333 | Q16: 14 | R16: =SUM(SMALL(Q16:Q27,{1,2,3,4,5,6}))/6 -> 9 | S16: 3000 | T16: 19 | U16: =SUM(SMALL(T16:T27,{1,2,3,4,5,6}))/6 -> 13.8 | W16: 15 | X16: =SUM(SMALL(W16:W27,{1,2,3,4,5,6}))/6 -> 10.5 | Y16: -600 | Z16: 20 | AA16: =SUM(SMALL(Z16:Z27,{1,2,3,4,5,6}))/6 -> 14.5 | AB16: 4000 | AC16: 21 | AD16: =SUM(SMALL(AC16:AC27,{1,2,3,4,5,6}))/6 -> 9.6666667 | AF16: 10 | AG16: =SUM(SMALL(AF16:AF27,{1,2,3,4,5,6}))/6 -> 3.8333333 | AI16: 12 | AJ16: =SUM(SMALL(AI16:AI27,{1,2,3,4,5,6}))/6 -> 10.5 | AL16: =17*0.8 -> 13.6 | AM16: =SUM(SMALL(AL16:AL27,{1,2,3,4,5,6}))/6 -> 10.533333 | AN16: 1200 | AO16: 11 | AP16: =SUM(SMALL(AO16:AO27,{1,2,3,4,5,6}))/6 -> 12.033333 | AR16: 11 | AS16: =SUM(SMALL(AR16:AR27,{1,2,3,4,5,6}))/6 -> 10.666667 | AT16: -1500 | AU16: 11 | AV16: =SUM(SMALL(AU16:AU27,{1,2,3,4,5,6}))/6 -> 12.5 | AW16: -200 | AX16: 18 | AY16: =SUM(SMALL(AX16:AX26,{1,2,3,4,5,6}))/6 -> 16.166667 | BA16: 11 | BB16: =SUM(SMALL(BA16:BA27,{1,2,3,4,5,6}))/6 -> 8.4333333 | BC16: -800 | BD16: 14 | BE16: =SUM(SMALL(BD16:BD27,{1,2,3,4,5,6}))/6 -> 10.333333 | BF16: -3300 | BG16: =22*0.8 -> 17.6 | BH16: 12.033333
B17: 5 | C17: =SUM(SMALL(B17:B28,{1,2,3,4,5,6}))/6 -> 5.8333333 | D17: 1800 | E17: 10 | F17: =SUM(SMALL(E17:E28,{1,2,3,4,5,6}))/6 -> 6 | H17: 2 | I17: =SUM(SMALL(H17:H28,{1,2,3,4,5,6}))/6 -> 2.6666667 | J17: 1500 | K17: 6 | L17: =SUM(SMALL(K17:K28,{1,2,3,4,5,6}))/6 -> 10 | N17: 21 | O17: =SUM(SMALL(N17:N28,{1,2,3,4,5,6}))/6 -> 12.833333 | Q17: 12 | R17: =SUM(SMALL(Q17:Q28,{1,2,3,4,5,6}))/6 -> 8.3333333 | T17: 22 | U17: =SUM(SMALL(T17:T28,{1,2,3,4,5,6}))/6 -> 13.633333 | W17: 14 | X17: =SUM(SMALL(W17:W28,{1,2,3,4,5,6}))/6 -> 10.5 | Z17: 15 | AA17: =SUM(SMALL(Z17:Z28,{1,2,3,4,5,6}))/6 -> 14.333333 | AB17: -300 | AC17: 10 | AD17: =SUM(SMALL(AC17:AC28,{1,2,3,4,5,6}))/6 -> 9.6666667 | AF17: 6 | AG17: =SUM(SMALL(AF17:AF28,{1,2,3,4,5,6}))/6 -> 3.8333333 | AI17: 16 | AJ17: =SUM(SMALL(AI17:AI28,{1,2,3,4,5,6}))/6 -> 10.5 | AK17: 1500 | AL17: 9 | AM17: =SUM(SMALL(AL17:AL28,{1,2,3,4,5,6}))/6 -> 10.6 | AN17: -300 | AO17: 17 | AP17: =SUM(SMALL(AO17:AO28,{1,2,3,4,5,6}))/6 -> 12.583333 | AR17: 12 | AS17: =SUM(SMALL(AR17:AR28,{1,2,3,4,5,6}))/6 -> 10.833333 | AU17: 17 | AV17: =SUM(SMALL(AU17:AU28,{1,2,3,4,5,6}))/6 -> 13 | AW17: -200 | AX17: 18 | AY17: =SUM(SMALL(AX17:AX26,{1,2,3,4,5,6}))/6 -> 16.166667 | AZ17: 3000 | BA17: 13 | BB17: =SUM(SMALL(BA17:BA28,{1,2,3,4,5,6}))/6 -> 8.4333333 | BC17: -3600 | BD17: 17 | BE17: =SUM(SMALL(BD17:BD28,{1,2,3,4,5,6}))/6 -> 9.6666667 | BG17: 14 | BH17: 12.033333
A18: 4000 | B18: 6 | C18: =SUM(SMALL(B18:B29,{1,2,3,4,5,6}))/6 -> 6.3333333 | E18: 8 | F18: =SUM(SMALL(E18:E29,{1,2,3,4,5,6}))/6 -> 5.5 | H18: 8 | I18: =SUM(SMALL(H18:H29,{1,2,3,4,5,6}))/6 -> 2.5 | K18: 16 | L18: =SUM(SMALL(K18:K29,{1,2,3,4,5,6}))/6 -> 11.166667 | N18: 17 | O18: =SUM(SMALL(N18:N29,{1,2,3,4,5,6}))/6 -> 12.833333 | Q18: 7 | R18: =SUM(SMALL(Q18:Q29,{1,2,3,4,5,6}))/6 -> 8.3333333 | T18: 17 | U18: =SUM(SMALL(T18:T29,{1,2,3,4,5,6}))/6 -> 13.633333 | W18: 14 | X18: =SUM(SMALL(W18:W29,{1,2,3,4,5,6}))/6 -> 10.5 | Y18: 1000 | Z18: 19 | AA18: =SUM(SMALL(Z18:Z29,{1,2,3,4,5,6}))/6 -> 14.666667 | AB18: -2000 | AC18: 13 | AD18: =SUM(SMALL(AC18:AC29,{1,2,3,4,5,6}))/6 -> 10.166667 | AF18: 10 | AG18: =SUM(SMALL(AF18:AF29,{1,2,3,4,5,6}))/6 -> 3.8333333 | AI18: 15 | AJ18: =SUM(SMALL(AI18:AI29,{1,2,3,4,5,6}))/6 -> 10.5 | AL18: =12*0.8 -> 9.6 | AM18: =SUM(SMALL(AL18:AL29,{1,2,3,4,5,6}))/6 -> 11.433333 | AO18: =12*1.1 -> 13.2 | AP18: =SUM(SMALL(AO18:AO29,{1,2,3,4,5,6}))/6 -> 12.583333 | AQ18: 1500 | AR18: 8 | AS18: =SUM(SMALL(AR18:AR29,{1,2,3,4,5,6}))/6 -> 11 | AT18: -600 | AU18: 15 | AV18: =SUM(SMALL(AU18:AU29,{1,2,3,4,5,6}))/6 -> 12.666667 | AW18: -200 | AX18: 18 | AY18: =SUM(SMALL(AX18:AX26,{1,2,3,4,5,6}))/6 -> 16.166667 | BA18: 10 | BB18: =SUM(SMALL(BA18:BA29,{1,2,3,4,5,6}))/6 -> 8.4333333 | BD18: 17 | BE18: =SUM(SMALL(BD18:BD29,{1,2,3,4,5,6}))/6 -> 9.5 | BG18: 9 | BH18: 11.7
A19: 2700 | B19: 6 | C19: =SUM(SMALL(B19:B30,{1,2,3,4,5,6}))/6 -> 6.3333333 | D19: -4000 | E19: 21 | F19: =SUM(SMALL(E19:E30,{1,2,3,4,5,6}))/6 -> 5.5 | H19: 4 | I19: =SUM(SMALL(H19:H30,{1,2,3,4,5,6}))/6 -> 1.8333333 | K19: 8 | L19: =SUM(SMALL(K19:K30,{1,2,3,4,5,6}))/6 -> 11.166667 | N19: 16 | O19: =SUM(SMALL(N19:N30,{1,2,3,4,5,6}))/6 -> 12.716667 | Q19: 9 | R19: =SUM(SMALL(Q19:Q30,{1,2,3,4,5,6}))/6 -> 8.8333333 | S19: 0 | T19: 15 | U19: 13.633333 | W19: 12 | X19: =SUM(SMALL(W19:W30,{1,2,3,4,5,6}))/6 -> 10.5 | Y19: -2000 | Z19: 19 | AA19: =SUM(SMALL(Z19:Z30,{1,2,3,4,5,6}))/6 -> 14.666667 | AC19: 10 | AD19: 9 | AF19: 5 | AG19: =SUM(SMALL(AF19:AF30,{1,2,3,4,5,6}))/6 -> 3.8333333 | AI19: 10 | AJ19: =SUM(SMALL(AI19:AI30,{1,2,3,4,5,6}))/6 -> 10.166667 | AL19: 11 | AM19: =SUM(SMALL(AL19:AL30,{1,2,3,4,5,6}))/6 -> 12.166667 | AO19: =13*1.1 -> 14.3 | AP19: =SUM(SMALL(AO19:AO30,{1,2,3,4,5,6}))/6 -> 12.716667 | AQ19: -3000 | AR19: 11 | AS19: =SUM(SMALL(AR19:AR30,{1,2,3,4,5,6}))/6 -> 11.833333 | AT19: 800 | AU19: 14 | AV19: =SUM(SMALL(AU19:AU30,{1,2,3,4,5,6}))/6 -> 12.666667 | AW19: -200 | AX19: 18 | AY19: =SUM(SMALL(AX19:AX26,{1,2,3,4,5,6}))/6 -> #NUM! | BA19: 10 | BB19: =SUM(SMALL(BA19:BA30,{1,2,3,4,5,6}))/6 -> 8.4333333 | BD19: 10 | BE19: =SUM(SMALL(BD19:BD30,{1,2,3,4,5,6}))/6 -> 9.5 | BF19: -3300 | BG19: 13 | BH19: 12.466667
B20: 8 | C20: =SUM(SMALL(B20:B31,{1,2,3,4,5,6}))/6 -> 6 | E20: 3 | F20: =SUM(SMALL(E20:E31,{1,2,3,4,5,6}))/6 -> 5.5 | H20: 3 | I20: =SUM(SMALL(H20:H31,{1,2,3,4,5,6}))/6 -> 1.8333333 | J20: 4000 | K20: 13 | L20: =SUM(SMALL(K20:K31,{1,2,3,4,5,6}))/6 -> 12 | M20: -3000 | N20: 15 | O20: =SUM(SMALL(N20:N31,{1,2,3,4,5,6}))/6 -> 12.716667 | Q20: 10 | R20: =SUM(SMALL(Q20:Q31,{1,2,3,4,5,6}))/6 -> 9.1666667 | S20: 4000 | T20: 15 | U20: 13.633333 | W20: 16 | X20: =SUM(SMALL(W20:W31,{1,2,3,4,5,6}))/6 -> 10 | Z20: 15 | AA20: =SUM(SMALL(Z20:Z31,{1,2,3,4,5,6}))/6 -> 14.666667 | AB20: 300 | AC20: 14 | AD20: 8.8333333 | AE20: -600 | AF20: 6 | AG20: =SUM(SMALL(AF20:AF31,{1,2,3,4,5,6}))/6 -> 4 | AI20: 12 | AJ20: =SUM(SMALL(AI20:AI31,{1,2,3,4,5,6}))/6 -> 10.333333 | AL20: 21 | AM20: =SUM(SMALL(AL20:AL31,{1,2,3,4,5,6}))/6 -> 13 | AN20: 150 | AO20: 11 | AP20: =SUM(SMALL(AO20:AO31,{1,2,3,4,5,6}))/6 -> 12.733333 | AQ20: 4000 | AR20: 17 | AS20: =SUM(SMALL(AR20:AR31,{1,2,3,4,5,6}))/6 -> 12.5 | AT20: -3600 | AU20: 18 | AV20: =SUM(SMALL(AU20:AU31,{1,2,3,4,5,6}))/6 -> 12.333333 | AW20: 1000 | AX20: 11 | AY20: =SUM(SMALL(AX20:AX26,{1,2,3,4,5,6}))/6 -> #NUM! | BA20: 16 | BB20: =SUM(SMALL(BA20:BA31,{1,2,3,4,5,6}))/6 -> 8.1 | BD20: 17 | BE20: =SUM(SMALL(BD20:BD31,{1,2,3,4,5,6}))/6 -> 9.8333333 | BF20: -1500 | BG20: 15 | BH20: 12.633333
B21: 5 | C21: =SUM(SMALL(B21:B32,{1,2,3,4,5,6}))/6 -> 6 | E21: 7 | F21: =SUM(SMALL(E21:E32,{1,2,3,4,5,6}))/6 -> 6.1666667 | H21: 5 | I21: =SUM(SMALL(H21:H32,{1,2,3,4,5,6}))/6 -> 2 | J21: 100 | K21: 15 | L21: =SUM(SMALL(K21:K32,{1,2,3,4,5,6}))/6 -> 12 | N21: 14 | O21: =SUM(SMALL(N21:N32,{1,2,3,4,5,6}))/6 -> 12.716667 | P21: -2400 | Q21: 10 | R21: =SUM(SMALL(Q21:Q32,{1,2,3,4,5,6}))/6 -> 9.3333333 | T21: 17 | U21: 13.3 | W21: 12 | X21: =SUM(SMALL(W21:W32,{1,2,3,4,5,6}))/6 -> 9.8333333 | Z21: 11 | AA21: =SUM(SMALL(Z21:Z32,{1,2,3,4,5,6}))/6 -> 15.166667 | AB21: -1600 | AC21: 9 | AD21: 8.8333333 | AE21: 100 | AF21: 9 | AG21: =SUM(SMALL(AF21:AF32,{1,2,3,4,5,6}))/6 -> 4.3333333 | AH21: 3000 | AI21: 11 | AJ21: =SUM(SMALL(AI21:AI32,{1,2,3,4,5,6}))/6 -> 10.333333 | AL21: 16 | AM21: =SUM(SMALL(AL21:AL32,{1,2,3,4,5,6}))/6 -> 13 | AN21: -900 | AO21: 20 | AP21: 13.3375 | AQ21: -2500 | AR21: 13 | AS21: =SUM(SMALL(AR21:AR32,{1,2,3,4,5,6}))/6 -> 12.5 | AU21: 16 | AV21: =SUM(SMALL(AU21:AU32,{1,2,3,4,5,6}))/6 -> 12.333333 | AX21: 18 | AY21: =SUM(SMALL(AX21:AX26,{1,2,3,4,5,6}))/6 -> #NUM! | AZ21: -1500 | BA21: 7 | BB21: =SUM(SMALL(BA21:BA32,{1,2,3,4,5,6}))/6 -> 8.1 | BD21: 12 | BE21: =SUM(SMALL(BD21:BD32,{1,2,3,4,5,6}))/6 -> 9.8333333 | BG21: 15 | BH21: 12.633333
B22: 8 | C22: =SUM(SMALL(B22:B33,{1,2,3,4,5,6}))/6 -> 6.5 | E22: 6 | F22: =SUM(SMALL(E22:E33,{1,2,3,4,5,6}))/6 -> 6.5 | H22: 3 | I22: =SUM(SMALL(H22:H33,{1,2,3,4,5,6}))/6 -> 2 | K22: 11 | L22: =SUM(SMALL(K22:K33,{1,2,3,4,5,6}))/6 -> 10.833333 | N22: 9 | O22: =SUM(SMALL(N22:N33,{1,2,3,4,5,6}))/6 -> 12.05 | P22: 600 | Q22: 11 | R22: =SUM(SMALL(Q22:Q33,{1,2,3,4,5,6}))/6 -> 9.6666667 | T22: 18 | U22: 13.3 | V22: -1000 | W22: 14 | X22: =SUM(SMALL(W22:W33,{1,2,3,4,5,6}))/6 -> 9.1666667 | Y22: -1200 | Z22: 20 | AA22: =SUM(SMALL(Z22:Z33,{1,2,3,4,5,6}))/6 -> 16.133333 | AB22: 900 | AC22: 17 | AD22: 9.5 | AE22: 3600 | AF22: 10 | AG22: =SUM(SMALL(AF22:AF33,{1,2,3,4,5,6}))/6 -> 4.3333333 | AH22: 0 | AI22: 14 | AJ22: =SUM(SMALL(AI22:AI33,{1,2,3,4,5,6}))/6 -> 10.666667 | AL22: 18 | AM22: =SUM(SMALL(AL22:AL33,{1,2,3,4,5,6}))/6 -> 13 | AO22: 16 | AP22: 13.3375 | AR22: 16 | AS22: =SUM(SMALL(AR22:AR33,{1,2,3,4,5,6}))/6 -> 13 | AU22: 13 | AV22: =SUM(SMALL(AU22:AU33,{1,2,3,4,5,6}))/6 -> 12.333333 | AX22: 14 | AZ22: -1000 | BA22: 15 | BB22: =SUM(SMALL(BA22:BA33,{1,2,3,4,5,6}))/6 -> 8.6 | BC22: 2000 | BD22: 7 | BE22: =SUM(SMALL(BD22:BD33,{1,2,3,4,5,6}))/6 -> 9.6666667 | BG22: 15 | BH22: 12.633333
B23: 12 | C23: =SUM(SMALL(B23:B34,{1,2,3,4,5,6}))/6 -> 5.6666667 | E23: 14 | F23: =SUM(SMALL(E23:E34,{1,2,3,4,5,6}))/6 -> 7.3333333 | G23: 1000 | H23: 5 | I23: =SUM(SMALL(H23:H34,{1,2,3,4,5,6}))/6 -> 2.1666667 | K23: 13 | L23: =SUM(SMALL(K23:K34,{1,2,3,4,5,6}))/6 -> 10.666667 | N23: 16 | O23: =SUM(SMALL(N23:N34,{1,2,3,4,5,6}))/6 -> 12.478571 | P23: 600 | Q23: 13 | R23: =SUM(SMALL(Q23:Q34,{1,2,3,4,5,6}))/6 -> 9.5 | T23: =16*0.8 -> 12.8 | U23: 13.3 | W23: 15 | X23: =SUM(SMALL(W23:W34,{1,2,3,4,5,6}))/6 -> 9.1666667 | Z23: 17 | AA23: =SUM(SMALL(Z23:Z34,{1,2,3,4,5,6}))/6 -> 16.133333 | AC23: 10 | AD23: 9.5 | AF23: 3 | AG23: =SUM(SMALL(AF23:AF34,{1,2,3,4,5,6}))/6 -> 4 | AH23: -4000 | AI23: 15 | AJ23: =SUM(SMALL(AI23:AI34,{1,2,3,4,5,6}))/6 -> 10.333333 | AL23: 17 | AM23: =SUM(SMALL(AL23:AL34,{1,2,3,4,5,6}))/6 -> 12.666667 | AO23: 13 | AP23: 13.283333 | AR23: 15 | AS23: =SUM(SMALL(AR23:AR34,{1,2,3,4,5,6}))/6 -> 13 | AU23: 13 | AV23: =SUM(SMALL(AU23:AU34,{1,2,3,4,5,6}))/6 -> 12.333333 | AX23: 18 | AZ23: -2000 | BA23: 9 | BB23: =SUM(SMALL(BA23:BA34,{1,2,3,4,5,6}))/6 -> 8.6 | BD23: 13 | BE23: =SUM(SMALL(BD23:BD34,{1,2,3,4,5,6}))/6 -> 10.5
B24: 14 | C24: =SUM(SMALL(B24:B35,{1,2,3,4,5,6}))/6 -> 5.6666667 | E24: 6 | F24: =SUM(SMALL(E24:E35,{1,2,3,4,5,6}))/6 -> 7.3333333 | G24: -1000 | H24: 12 | I24: =SUM(SMALL(H24:H35,{1,2,3,4,5,6}))/6 -> 2.1666667 | K24: 13 | L24: =SUM(SMALL(K24:K35,{1,2,3,4,5,6}))/6 -> 9.6666667 | N24: 14 | O24: =SUM(SMALL(N24:N35,{1,2,3,4,5,6}))/6 -> 11.761905 | P24: -2100 | Q24: =15*0.8 -> 12 | R24: =SUM(SMALL(Q24:Q35,{1,2,3,4,5,6}))/6 -> 9.1666667 | S24: -500 | T24: 15 | U24: 13.833333 | V24: 3000 | W24: 10 | X24: =SUM(SMALL(W24:W35,{1,2,3,4,5,6}))/6 -> 9.1666667 | Z24: 15 | AA24: =SUM(SMALL(Z24:Z35,{1,2,3,4,5,6}))/6 -> 15.466667 | AC24: 19 | AD24: 10 | AF24: 6 | AG24: =SUM(SMALL(AF24:AF35,{1,2,3,4,5,6}))/6 -> 4.8333333 | AI24: 11 | AJ24: =SUM(SMALL(AI24:AI35,{1,2,3,4,5,6}))/6 -> 10.333333 | AK24: 1000 | AL24: 14 | AM24: =SUM(SMALL(AL24:AL35,{1,2,3,4,5,6}))/6 -> 12.666667 | AO24: 16 | AP24: 13.554167 | AR24: 12 | AS24: =SUM(SMALL(AR24:AR35,{1,2,3,4,5,6}))/6 -> 13 | AU24: 14 | AV24: =SUM(SMALL(AU24:AU35,{1,2,3,4,5,6}))/6 -> 12.5 | BA24: =11*0.8 -> 8.8 | BB24: =SUM(SMALL(BA24:BA35,{1,2,3,4,5,6}))/6 -> 8.7666667 | BC24: 3000 | BD24: 13 | BE24: =SUM(SMALL(BD24:BD35,{1,2,3,4,5,6}))/6 -> 10.166667
B25: 8 | C25: =SUM(SMALL(B25:B36,{1,2,3,4,5,6}))/6 -> 5.5 | E25: 6 | F25: =SUM(SMALL(E25:E36,{1,2,3,4,5,6}))/6 -> 8.1666667 | G25: 0 | H25: 1 | I25: =SUM(SMALL(H25:H36,{1,2,3,4,5,6}))/6 -> 2.1666667 | K25: 14 | L25: =SUM(SMALL(K25:K36,{1,2,3,4,5,6}))/6 -> 9 | M25: -1500 | N25: 13 | O25: =SUM(SMALL(N25:N36,{1,2,3,4,5,6}))/6 -> 11.811905 | P25: -1000 | Q25: =12*1.1 -> 13.2 | R25: =SUM(SMALL(Q25:Q36,{1,2,3,4,5,6}))/6 -> 9.1666667 | S25: 3300 | T25: 10 | U25: 14 | V25: 2000 | W25: 12 | X25: =SUM(SMALL(W25:W36,{1,2,3,4,5,6}))/6 -> 9.5 | Z25: 18 | AA25: =SUM(SMALL(Z25:Z36,{1,2,3,4,5,6}))/6 -> 16.133333 | AB25: -1500 | AC25: 14 | AD25: 9.6666667 | AF25: -3 | AG25: =SUM(SMALL(AF25:AF36,{1,2,3,4,5,6}))/6 -> 4.8333333 | AH25: 1500 | AI25: 15 | AJ25: =SUM(SMALL(AI25:AI36,{1,2,3,4,5,6}))/6 -> 10.666667 | AK25: 1000 | AL25: 11 | AM25: =SUM(SMALL(AL25:AL36,{1,2,3,4,5,6}))/6 -> 13 | AO25: 12 | AP25: 12.95 | AR25: 21 | AS25: =SUM(SMALL(AR25:AR36,{1,2,3,4,5,6}))/6 -> 13.166667 | AU25: 15 | AV25: =SUM(SMALL(AU25:AU36,{1,2,3,4,5,6}))/6 -> 12.666667 | AZ25: -2100 | BA25: =11*0.8 -> 8.8 | BB25: =SUM(SMALL(BA25:BA36,{1,2,3,4,5,6}))/6 -> 8.6333333 | BD25: 8 | BE25: =SUM(SMALL(BD25:BD36,{1,2,3,4,5,6}))/6 -> 10.166667
B26: 7 | C26: =SUM(SMALL(B26:B37,{1,2,3,4,5,6}))/6 -> 5.5 | E26: 11 | F26: =SUM(SMALL(E26:E37,{1,2,3,4,5,6}))/6 -> 8.5 | G26: 0 | H26: 4 | I26: =SUM(SMALL(H26:H37,{1,2,3,4,5,6}))/6 -> 2.1666667 | K26: 12 | L26: =SUM(SMALL(K26:K37,{1,2,3,4,5,6}))/6 -> 8.5 | M26: -1500 | N26: 12 | O26: =SUM(SMALL(N26:N37,{1,2,3,4,5,6}))/6 -> 12.045238 | P26: 1500 | Q26: 8 | R26: =SUM(SMALL(Q26:Q37,{1,2,3,4,5,6}))/6 -> 8.6666667 | T26: 15 | U26: 14.666667 | V26: 1000 | W26: 8 | X26: =SUM(SMALL(W26:W37,{1,2,3,4,5,6}))/6 -> 9.3333333 | Z26: 22 | AA26: =SUM(SMALL(Z26:Z37,{1,2,3,4,5,6}))/6 -> 15.466667 | AC26: 6 | AD26: 9.3333333 | AF26: 8 | AG26: =SUM(SMALL(AF26:AF37,{1,2,3,4,5,6}))/6 -> 6.1666667 | AH26: 1000 | AI26: 12 | AJ26: =SUM(SMALL(AI26:AI37,{1,2,3,4,5,6}))/6 -> 10.666667 | AK26: -3000 | AL26: 18 | AM26: =SUM(SMALL(AL26:AL37,{1,2,3,4,5,6}))/6 -> 13.666667 | AO26: 12 | AP26: 13.3875 | AR26: 10 | AS26: =SUM(SMALL(AR26:AR37,{1,2,3,4,5,6}))/6 -> 13.166667 | AU26: 14 | AV26: =SUM(SMALL(AU26:AU37,{1,2,3,4,5,6}))/6 -> 12.166667 | AZ26: 2000 | BA26: 7 | BB26: =SUM(SMALL(BA26:BA37,{1,2,3,4,5,6}))/6 -> 8.6666667 | BC26: 2000 | BD26: 12 | BE26: =SUM(SMALL(BD26:BD37,{1,2,3,4,5,6}))/6 -> 10.833333
A27: 1000 | B27: 6 | C27: =SUM(SMALL(B27:B38,{1,2,3,4,5,6}))/6 -> 5.6666667 | E27: 9 | F27: =SUM(SMALL(E27:E38,{1,2,3,4,5,6}))/6 -> 8.5 | H27: 3 | I27: =SUM(SMALL(H27:H38,{1,2,3,4,5,6}))/6 -> 2.1666667 | K27: 10 | L27: =SUM(SMALL(K27:K38,{1,2,3,4,5,6}))/6 -> 8.5 | M27: 2000 | N27: 19 | O27: =SUM(SMALL(N27:N38,{1,2,3,4,5,6}))/6 -> 11.378571 | P27: -1800 | Q27: 10 | R27: =SUM(SMALL(Q27:Q38,{1,2,3,4,5,6}))/6 -> 9.1666667 | T27: 16 | U27: 14.5 | W27: 9 | X27: =SUM(SMALL(W27:W38,{1,2,3,4,5,6}))/6 -> 8.8333333 | Z27: 14 | AA27: =SUM(SMALL(Z27:Z38,{1,2,3,4,5,6}))/6 -> 14.966667 | AC27: 19 | AD27: 10.5 | AF27: 9 | AG27: =SUM(SMALL(AF27:AF38,{1,2,3,4,5,6}))/6 -> 6.1666667 | AH27: 1500 | AI27: 7 | AJ27: =SUM(SMALL(AI27:AI38,{1,2,3,4,5,6}))/6 -> 10.833333 | AL27: 9 | AM27: =SUM(SMALL(AL27:AL38,{1,2,3,4,5,6}))/6 -> 12.833333 | AN27: 2100 | AO27: =13*1.125 -> 14.625 | AP27: 13.8875 | AR27: 12 | AS27: =SUM(SMALL(AR27:AR38,{1,2,3,4,5,6}))/6 -> 14.166667 | AT27: 2000 | AU27: 10 | AV27: =SUM(SMALL(AU27:AU38,{1,2,3,4,5,6}))/6 -> 11.833333 | BA27: 10 | BB27: =SUM(SMALL(BA27:BA38,{1,2,3,4,5,6}))/6 -> 8.8333333 | BC27: -4000 | BD27: 15 | BE27: =SUM(SMALL(BD27:BD38,{1,2,3,4,5,6}))/6 -> 10.833333
A28: 1000 | B28: 10 | C28: =SUM(SMALL(B28:B39,{1,2,3,4,5,6}))/6 -> 5.5 | E28: 15 | F28: =SUM(SMALL(E28:E39,{1,2,3,4,5,6}))/6 -> 8.8333333 | H28: 8 | I28: =SUM(SMALL(H28:H39,{1,2,3,4,5,6}))/6 -> 2.3333333 | J28: -1000 | K28: 13 | L28: =SUM(SMALL(K28:K39,{1,2,3,4,5,6}))/6 -> 9 | M28: 2000 | N28: 16 | O28: =SUM(SMALL(N28:N39,{1,2,3,4,5,6}))/6 -> 11.378571 | P28: 600 | Q28: 6 | R28: =SUM(SMALL(Q28:Q39,{1,2,3,4,5,6}))/6 -> 9 | S28: 2000 | T28: 14 | U28: 14.5 | V28: -2000 | W28: 12 | X28: =SUM(SMALL(W28:W39,{1,2,3,4,5,6}))/6 -> 9.3333333 | Y28: 1200 | Z28: 16 | AA28: =SUM(SMALL(Z28:Z39,{1,2,3,4,5,6}))/6 -> 15.466667 | AB28: -2000 | AC28: 13 | AD28: 10.5 | AF28: 6 | AG28: =SUM(SMALL(AF28:AF39,{1,2,3,4,5,6}))/6 -> 6.1666667 | AH28: 0 | AI28: 13 | AJ28: =SUM(SMALL(AI28:AI39,{1,2,3,4,5,6}))/6 -> 11.833333 | AL28: 14 | AM28: =SUM(SMALL(AL28:AL39,{1,2,3,4,5,6}))/6 -> 14 | AO28: =12*1.2 -> 14.4 | AP28: 13.783333 | AR28: 13 | AS28: =SUM(SMALL(AR28:AR39,{1,2,3,4,5,6}))/6 -> 14.666667 | AU28: 15 | AV28: =SUM(SMALL(AU28:AU39,{1,2,3,4,5,6}))/6 -> 12.5 | AZ28: -1500 | BA28: 11 | BB28: =SUM(SMALL(BA28:BA39,{1,2,3,4,5,6}))/6 -> 7.8333333 | BD28: 9 | BE28: =SUM(SMALL(BD28:BD39,{1,2,3,4,5,6}))/6 -> 10.833333
B29: 13 | C29: =SUM(SMALL(B29:B40,{1,2,3,4,5,6}))/6 -> 5.1666667 | E29: 5 | F29: =SUM(SMALL(E29:E40,{1,2,3,4,5,6}))/6 -> 8.8333333 | H29: 1 | I29: =SUM(SMALL(H29:H40,{1,2,3,4,5,6}))/6 -> 2.1666667 | K29: 15 | L29: =SUM(SMALL(K29:K40,{1,2,3,4,5,6}))/6 -> 7.6666667 | N29: =17*1.2 -> 20.4 | O29: =SUM(SMALL(N29:N40,{1,2,3,4,5,6}))/6 -> 10.978571 | P29: -2000 | Q29: 12 | R29: =SUM(SMALL(Q29:Q40,{1,2,3,4,5,6}))/6 -> 9.1666667 | T29: =17*1.1 -> 18.7 | U29: 14.5 | V29: 0 | W29: 15 | X29: =SUM(SMALL(W29:W40,{1,2,3,4,5,6}))/6 -> 9.5 | Y29: 1000 | Z29: 22 | AA29: =SUM(SMALL(Z29:Z40,{1,2,3,4,5,6}))/6 -> 15.966667 | AC29: 19 | AD29: 10.5 | AE29: -3000 | AF29: 14 | AG29: =SUM(SMALL(AF29:AF40,{1,2,3,4,5,6}))/6 -> 6.1666667 | AI29: 13 | AJ29: =SUM(SMALL(AI29:AI40,{1,2,3,4,5,6}))/6 -> 12.166667 | AK29: -4000 | AL29: 23 | AM29: =SUM(SMALL(AL29:AL40,{1,2,3,4,5,6}))/6 -> 14 | AO29: 15 | AP29: 13.383333 | AR29: 16 | AS29: =SUM(SMALL(AR29:AR40,{1,2,3,4,5,6}))/6 -> 15.5 | AT29: -3000 | AU29: 12 | AV29: =SUM(SMALL(AU29:AU40,{1,2,3,4,5,6}))/6 -> 12.5 | BA29: 10 | BB29: =SUM(SMALL(BA29:BA40,{1,2,3,4,5,6}))/6 -> 7.5 | BD29: 11 | BE29: =SUM(SMALL(BD29:BD40,{1,2,3,4,5,6}))/6 -> 10.833333
B30: 6 | C30: =SUM(SMALL(B30:B41,{1,2,3,4,5,6}))/6 -> 5.1666667 | E30: 11 | F30: =SUM(SMALL(E30:E41,{1,2,3,4,5,6}))/6 -> 9.3333333 | G30: -1500 | H30: 0 | I30: =SUM(SMALL(H30:H41,{1,2,3,4,5,6}))/6 -> 2.6666667 | K30: 20 | L30: =SUM(SMALL(K30:K41,{1,2,3,4,5,6}))/6 -> 7.1666667 | M30: 2000 | N30: =13*1.1 -> 14.3 | O30: =SUM(SMALL(N30:N41,{1,2,3,4,5,6}))/6 -> 10.978571 | P30: -1000 | Q30: 15 | R30: =SUM(SMALL(Q30:Q41,{1,2,3,4,5,6}))/6 -> 8.6666667 | V30: 600 | W30: 13 | X30: =SUM(SMALL(W30:W41,{1,2,3,4,5,6}))/6 -> 8.1666667 | Z30: 20 | AA30: =SUM(SMALL(Z30:Z41,{1,2,3,4,5,6}))/6 -> 15.966667 | AE30: 3000 | AF30: 6 | AG30: =SUM(SMALL(AF30:AF41,{1,2,3,4,5,6}))/6 -> 6 | AH30: 1500 | AI30: 10 | AJ30: =SUM(SMALL(AI30:AI41,{1,2,3,4,5,6}))/6 -> 11.833333 | AK30: 1500 | AL30: 14 | AM30: =SUM(SMALL(AL30:AL41,{1,2,3,4,5,6}))/6 -> 14 | AO30: 14 | AP30: 13.383333 | AQ30: 2400 | AR30: 19 | AS30: =SUM(SMALL(AR30:AR41,{1,2,3,4,5,6}))/6 -> 16 | AT30: 3000 | AU30: 21 | AV30: =SUM(SMALL(AU30:AU41,{1,2,3,4,5,6}))/6 -> 13 | AZ30: -600 | BA30: 21 | BB30: =SUM(SMALL(BA30:BA41,{1,2,3,4,5,6}))/6 -> 7.5 | BD30: 16 | BE30: =SUM(SMALL(BD30:BD41,{1,2,3,4,5,6}))/6 -> 10.666667
A31: 600 | B31: 4 | C31: =SUM(SMALL(B31:B42,{1,2,3,4,5,6}))/6 -> 5.5 | E31: 7 | F31: =SUM(SMALL(E31:E42,{1,2,3,4,5,6}))/6 -> 9 | G31: 300 | H31: 4 | I31: =SUM(SMALL(H31:H42,{1,2,3,4,5,6}))/6 -> 2.6666667 | K31: 13 | L31: =SUM(SMALL(K31:K42,{1,2,3,4,5,6}))/6 -> 6.8333333 | M31: -4000 | N31: 16 | O31: =SUM(SMALL(N31:N42,{1,2,3,4,5,6}))/6 -> 10.995238 | Q31: 11 | R31: 8.6666667 | V31: 4000 | W31: 9 | X31: =SUM(SMALL(W31:W42,{1,2,3,4,5,6}))/6 -> 7.8333333 | Y31: -1500 | Z31: 22 | AA31: =SUM(SMALL(Z31:Z42,{1,2,3,4,5,6}))/6 -> 15.55 | AF31: 8 | AG31: =SUM(SMALL(AF31:AF42,{1,2,3,4,5,6}))/6 -> 6.3333333 | AH31: 1500 | AI31: 11 | AJ31: 12 | AL31: 19 | AM31: =SUM(SMALL(AL31:AL42,{1,2,3,4,5,6}))/6 -> 14 | AO31: 15 | AP31: 13.883333 | AR31: 24 | AS31: =SUM(SMALL(AR31:AR42,{1,2,3,4,5,6}))/6 -> 16 | AT31: 4000 | AU31: 12 | AV31: =SUM(SMALL(AU31:AU42,{1,2,3,4,5,6}))/6 -> 12.666667 | AZ31: 1400 | BA31: 8 | BB31: =SUM(SMALL(BA31:BA42,{1,2,3,4,5,6}))/6 -> 7 | BD31: 13 | BE31: =SUM(SMALL(BD31:BD42,{1,2,3,4,5,6}))/6 -> 10.666667
A32: -400 | B32: 11 | C32: =SUM(SMALL(B32:B43,{1,2,3,4,5,6}))/6 -> 6.1666667 | E32: 12 | F32: =SUM(SMALL(E32:E43,{1,2,3,4,5,6}))/6 -> 9.3333333 | G32: 2000 | H32: 4 | I32: =SUM(SMALL(H32:H43,{1,2,3,4,5,6}))/6 -> 2.6666667 | J32: 0 | K32: 13 | L32: =SUM(SMALL(K32:K43,{1,2,3,4,5,6}))/6 -> 6.8333333 | M32: -600 | N32: =18*0.8 -> 14.4 | O32: =SUM(SMALL(N32:N43,{1,2,3,4,5,6}))/6 -> 10.261905 | Q32: 12 | R32: 8.3333333 | V32: -4000 | W32: 11 | X32: =SUM(SMALL(W32:W43,{1,2,3,4,5,6}))/6 -> 8 | Z32: =19*1.1 -> 20.9 | AA32: =SUM(SMALL(Z32:Z43,{1,2,3,4,5,6}))/6 -> 15.55 | AE32: 4000 | AF32: 10 | AG32: =SUM(SMALL(AF32:AF43,{1,2,3,4,5,6}))/6 -> 6.5 | AH32: 1600 | AI32: 17 | AJ32: 12.333333 | AK32: 300 | AL32: 17 | AM32: =SUM(SMALL(AL32:AL43,{1,2,3,4,5,6}))/6 -> 14 | AR32: 22 | AS32: =SUM(SMALL(AR32:AR43,{1,2,3,4,5,6}))/6 -> 14.666667 | AU32: 15 | AV32: =SUM(SMALL(AU32:AU43,{1,2,3,4,5,6}))/6 -> 13.166667 | AZ32: -2700 | BA32: 18 | BB32: =SUM(SMALL(BA32:BA43,{1,2,3,4,5,6}))/6 -> 7.1666667 | BD32: 12 | BE32: =SUM(SMALL(BD32:BD43,{1,2,3,4,5,6}))/6 -> 10.666667
A33: -1500 | B33: 8 | C33: =SUM(SMALL(B33:B44,{1,2,3,4,5,6}))/6 -> 6 | D33: 400 | E33: 11 | F33: =SUM(SMALL(E33:E44,{1,2,3,4,5,6}))/6 -> 9.3333333 | G33: -1000 | H33: 5 | I33: =SUM(SMALL(H33:H44,{1,2,3,4,5,6}))/6 -> 2 | K33: 6 | L33: =SUM(SMALL(K33:K44,{1,2,3,4,5,6}))/6 -> 6.8333333 | M33: 2000 | N33: 10 | O33: =SUM(SMALL(N33:N44,{1,2,3,4,5,6}))/6 -> 10.261905 | P33: 2400 | Q33: 18 | R33: 8.3333333 | W33: 8 | X33: =SUM(SMALL(W33:W44,{1,2,3,4,5,6}))/6 -> 8 | Z33: =21*0.8 -> 16.8 | AA33: =SUM(SMALL(Z33:Z44,{1,2,3,4,5,6}))/6 -> 15.55 | AF33: 11 | AG33: =SUM(SMALL(AF33:AF44,{1,2,3,4,5,6}))/6 -> 6.5 | AH33: -4000 | AI33: 16 | AJ33: 12.333333 | AK33: -4000 | AL33: 16 | AM33: =SUM(SMALL(AL33:AL44,{1,2,3,4,5,6}))/6 -> 13.166667 | AR33: 18 | AS33: =SUM(SMALL(AR33:AR44,{1,2,3,4,5,6}))/6 -> 14.666667 | AU33: 17 | AV33: =SUM(SMALL(AU33:AU44,{1,2,3,4,5,6}))/6 -> 12.333333 | BA33: 12 | BB33: =SUM(SMALL(BA33:BA44,{1,2,3,4,5,6}))/6 -> 7.1666667 | BD33: 11 | BE33: =SUM(SMALL(BD33:BD44,{1,2,3,4,5,6}))/6 -> 10.666667
B34: 3 | C34: =SUM(SMALL(B34:B45,{1,2,3,4,5,6}))/6 -> 6 | D34: 4000 | E34: 18 | F34: =SUM(SMALL(E34:E45,{1,2,3,4,5,6}))/6 -> 8.8333333 | G34: -2000 | H34: 7 | I34: =SUM(SMALL(H34:H45,{1,2,3,4,5,6}))/6 -> 1.6666667 | K34: 10 | L34: =SUM(SMALL(K34:K45,{1,2,3,4,5,6}))/6 -> 7.3333333 | M34: 1000 | N34: =9/14*18 -> 11.571429 | O34: =SUM(SMALL(N34:N45,{1,2,3,4,5,6}))/6 -> 9.7202381 | P34: -2100 | Q34: 10 | R34: 8.1666667 | V34: -3000 | W34: 13 | X34: =SUM(SMALL(W34:W45,{1,2,3,4,5,6}))/6 -> 8 | Y34: -3300 | Z34: 19 | AA34: =SUM(SMALL(Z34:Z45,{1,2,3,4,5,6}))/6 -> 15.25 | AF34: 6 | AG34: =SUM(SMALL(AF34:AF45,{1,2,3,4,5,6}))/6 -> 6.5 | AI34: 11 | AJ34: 12.333333 | AK34: 720 | AL34: 14 | AM34: =SUM(SMALL(AL34:AL45,{1,2,3,4,5,6}))/6 -> 13.166667 | AR34: 22 | AS34: =SUM(SMALL(AR34:AR45,{1,2,3,4,5,6}))/6 -> 14.333333 | AU34: 13 | AV34: =SUM(SMALL(AU34:AU45,{1,2,3,4,5,6}))/6 -> 12.333333 | AZ34: 0 | BA34: 11 | BB34: 6.5 | BC34: -1500 | BD34: 12 | BE34: =SUM(SMALL(BD34:BD45,{1,2,3,4,5,6}))/6 -> 10.833333
B35: 14 | C35: =SUM(SMALL(B35:B46,{1,2,3,4,5,6}))/6 -> 6.1666667 | E35: 17 | F35: =SUM(SMALL(E35:E46,{1,2,3,4,5,6}))/6 -> 8.8333333 | H35: 4 | I35: =SUM(SMALL(H35:H46,{1,2,3,4,5,6}))/6 -> 1.6666667 | K35: 7 | L35: =SUM(SMALL(K35:K46,{1,2,3,4,5,6}))/6 -> 7.3333333 | N35: 10 | O35: =SUM(SMALL(N35:N46,{1,2,3,4,5,6}))/6 -> 9.6583333 | Q35: 10 | R35: 8.1666667 | V35: 1000 | W35: 15 | X35: =SUM(SMALL(W35:W46,{1,2,3,4,5,6}))/6 -> 7.3333333 | Z35: 13 | AA35: =SUM(SMALL(Z35:Z46,{1,2,3,4,5,6}))/6 -> 14.583333 | AF35: 11 | AG35: =SUM(SMALL(AF35:AF46,{1,2,3,4,5,6}))/6 -> 6.5 | AH35: -3000 | AI35: 19 | AJ35: 11.833333 | AK35: -300 | AL35: 18 | AM35: =SUM(SMALL(AL35:AL46,{1,2,3,4,5,6}))/6 -> 13.5 | AR35: 15 | AS35: =SUM(SMALL(AR35:AR46,{1,2,3,4,5,6}))/6 -> 14.333333 | AU35: 17 | AV35: =SUM(SMALL(AU35:AU46,{1,2,3,4,5,6}))/6 -> 12.333333 | AZ35: -4000 | BA35: 24 | BB35: 6.5 | BC35: -1500 | BD35: 10 | BE35: =SUM(SMALL(BD35:BD46,{1,2,3,4,5,6}))/6 -> 11.166667
A36: 1800 | B36: 7 | C36: =SUM(SMALL(B36:B47,{1,2,3,4,5,6}))/6 -> 5.1666667 | D36: -1800 | E36: 13 | F36: =SUM(SMALL(E36:E47,{1,2,3,4,5,6}))/6 -> 8.8333333 | G36: 2000 | H36: 7 | I36: =SUM(SMALL(H36:H47,{1,2,3,4,5,6}))/6 -> 1.3333333 | K36: 9 | L36: =SUM(SMALL(K36:K47,{1,2,3,4,5,6}))/6 -> 8 | N36: 15 | O36: =SUM(SMALL(N36:N47,{1,2,3,4,5,6}))/6 -> 10.158333 | Q36: =14*0.8 -> 11.2 | R36: 7.6666667 | W36: 19 | X36: =SUM(SMALL(W36:W47,{1,2,3,4,5,6}))/6 -> 7.3333333 | Y36: -480 | Z36: 20 | AA36: =SUM(SMALL(Z36:Z47,{1,2,3,4,5,6}))/6 -> 15.25 | AF36: 6 | AG36: =SUM(SMALL(AF36:AF47,{1,2,3,4,5,6}))/6 -> 6.1666667 | AI36: 15 | AJ36: 11.666667 | AL36: 18 | AM36: =SUM(SMALL(AL36:AL47,{1,2,3,4,5,6}))/6 -> 12.761905 | AQ36: 2000 | AR36: 13 | AS36: =SUM(SMALL(AR36:AR47,{1,2,3,4,5,6}))/6 -> 13.833333 | AU36: 15 | AV36: =SUM(SMALL(AU36:AU47,{1,2,3,4,5,6}))/6 -> 12.333333 | BA36: 8 | BB36: 6.5 | BC36: 4000 | BD36: 12 | BE36: =SUM(SMALL(BD36:BD47,{1,2,3,4,5,6}))/6 -> 12
B37: 9 | C37: =SUM(SMALL(B37:B48,{1,2,3,4,5,6}))/6 -> 5.1666667 | E37: 8 | F37: =SUM(SMALL(E37:E48,{1,2,3,4,5,6}))/6 -> 8 | G37: 2000 | H37: 1 | I37: =SUM(SMALL(H37:H48,{1,2,3,4,5,6}))/6 -> 1.3333333 | K37: 9 | L37: =SUM(SMALL(K37:K48,{1,2,3,4,5,6}))/6 -> 8.3333333 | N37: 17 | O37: =SUM(SMALL(N37:N48,{1,2,3,4,5,6}))/6 -> 9.4916667 | P37: 0 | Q37: 8 | R37: 7.6666667 | V37: 0 | W37: 11 | X37: =SUM(SMALL(W37:W48,{1,2,3,4,5,6}))/6 -> 7.3333333 | Y37: 300 | Z37: 14 | AA37: =SUM(SMALL(Z37:Z48,{1,2,3,4,5,6}))/6 -> 14.916667 | AF37: 5 | AG37: =SUM(SMALL(AF37:AF48,{1,2,3,4,5,6}))/6 -> 6.3333333 | AI37: 15 | AJ37: 11.666667 | AK37: 2400 | AL37: 15 | AM37: =SUM(SMALL(AL37:AL48,{1,2,3,4,5,6}))/6 -> 11.428571 | AQ37: -600 | AR37: 19 | AS37: =SUM(SMALL(AR37:AR48,{1,2,3,4,5,6}))/6 -> 13.666667 | AU37: 12 | AV37: =SUM(SMALL(AU37:AU48,{1,2,3,4,5,6}))/6 -> 12 | BA37: 9 | BB37: 6.6666667 | BC37: -2500 | BD37: 17 | BE37: =SUM(SMALL(BD37:BD48,{1,2,3,4,5,6}))/6 -> 12.666667
B38: 12 | C38: =SUM(SMALL(B38:B49,{1,2,3,4,5,6}))/6 -> 5 | E38: 11 | F38: =SUM(SMALL(E38:E49,{1,2,3,4,5,6}))/6 -> 8 | G38: 0 | H38: 5 | I38: =SUM(SMALL(H38:H49,{1,2,3,4,5,6}))/6 -> 1.5 | K38: 14 | L38: =SUM(SMALL(K38:K49,{1,2,3,4,5,6}))/6 -> 8.8333333 | M38: 2400 | N38: 8 | O38: =SUM(SMALL(N38:N49,{1,2,3,4,5,6}))/6 -> 9.4916667 | P38: -3000 | Q38: 12 | R38: 7.8333333 | V38: 4000 | W38: 5 | X38: =SUM(SMALL(W38:W49,{1,2,3,4,5,6}))/6 -> 6.5 | Y38: -2400 | Z38: 16 | AA38: =SUM(SMALL(Z38:Z49,{1,2,3,4,5,6}))/6 -> 15.416667 | AF38: 10 | AG38: =SUM(SMALL(AF38:AF49,{1,2,3,4,5,6}))/6 -> 7 | AH38: -3000 | AI38: 15 | AJ38: 11.166667 | AK38: -600 | AL38: 11 | AM38: =SUM(SMALL(AL38:AL49,{1,2,3,4,5,6}))/6 -> 11.428571 | AQ38: -2100 | AR38: 16 | AS38: =SUM(SMALL(AR38:AR49,{1,2,3,4,5,6}))/6 -> 13.5 | AT38: 1500 | AU38: 12 | AV38: =SUM(SMALL(AU38:AU49,{1,2,3,4,5,6}))/6 -> 12.333333 | BA38: 8 | BB38: 6.6666667 | BD38: 19 | BE38: =SUM(SMALL(BD38:BD49,{1,2,3,4,5,6}))/6 -> 12.666667
B39: 5 | C39: =SUM(SMALL(B39:B50,{1,2,3,4,5,6}))/6 -> 5 | E39: 16 | F39: =SUM(SMALL(E39:E50,{1,2,3,4,5,6}))/6 -> 8 | G39: 600 | H39: =12*0.8 -> 9.6 | I39: =SUM(SMALL(H39:H50,{1,2,3,4,5,6}))/6 -> 1.5 | J39: -1200 | K39: 16 | L39: =SUM(SMALL(K39:K50,{1,2,3,4,5,6}))/6 -> 8.8333333 | M39: 2000 | N39: 18 | O39: =SUM(SMALL(N39:N50,{1,2,3,4,5,6}))/6 -> 10.158333 | Q39: 9 | R39: 7.8333333 | V39: -3000 | W39: 13 | X39: =SUM(SMALL(W39:W50,{1,2,3,4,5,6}))/6 -> 7.3333333 | Y39: 600 | Z39: 17 | AA39: =SUM(SMALL(Z39:Z50,{1,2,3,4,5,6}))/6 -> 15.416667 | AF39: 9 | AG39: =SUM(SMALL(AF39:AF50,{1,2,3,4,5,6}))/6 -> 6.8333333 | AH39: -900 | AI39: 13 | AJ39: 10.166667 | AK39: -600 | AL39: 16 | AM39: =SUM(SMALL(AL39:AL50,{1,2,3,4,5,6}))/6 -> 12.095238 | AQ39: -1200 | AR39: 15 | AS39: =SUM(SMALL(AR39:AR50,{1,2,3,4,5,6}))/6 -> 13.5 | AT39: 3000 | AU39: 14 | AV39: =SUM(SMALL(AU39:AU50,{1,2,3,4,5,6}))/6 -> 12.833333 | BA39: 4 | BB39: 6.9333333 | BD39: 12 | BE39: =SUM(SMALL(BD39:BD50,{1,2,3,4,5,6}))/6 -> 12.666667
B40: 6 | C40: =SUM(SMALL(B40:B51,{1,2,3,4,5,6}))/6 -> 5.3333333 | E40: 12 | F40: =SUM(SMALL(E40:E51,{1,2,3,4,5,6}))/6 -> 8 | G40: -600 | H40: 3 | I40: =SUM(SMALL(H40:H51,{1,2,3,4,5,6}))/6 -> 1.3333333 | K40: 5 | L40: =SUM(SMALL(K40:K51,{1,2,3,4,5,6}))/6 -> 8.8333333 | N40: 12 | O40: =SUM(SMALL(N40:N51,{1,2,3,4,5,6}))/6 -> 10.158333 | Q40: 7 | R40: 7.8333333 | W40: =18*0.8 -> 14.4 | X40: =SUM(SMALL(W40:W51,{1,2,3,4,5,6}))/6 -> 7 | Y40: 900 | Z40: 21 | AA40: =SUM(SMALL(Z40:Z51,{1,2,3,4,5,6}))/6 -> 15.916667 | AF40: 6 | AG40: =SUM(SMALL(AF40:AF51,{1,2,3,4,5,6}))/6 -> 6.8333333 | AH40: -1500 | AI40: 20 | AJ40: 10.166667 | AK40: -900 | AL40: 14 | AM40: =SUM(SMALL(AL40:AL51,{1,2,3,4,5,6}))/6 -> 11.095238 | AQ40: 600 | AR40: 19 | AS40: =SUM(SMALL(AR40:AR51,{1,2,3,4,5,6}))/6 -> 13 | AT40: -4000 | AU40: 20 | AV40: =SUM(SMALL(AU40:AU51,{1,2,3,4,5,6}))/6 -> 13 | BA40: 8 | BB40: 7.7666667 | BD40: 9 | BE40: =SUM(SMALL(BD40:BD51,{1,2,3,4,5,6}))/6 -> 13
B41: 8 | C41: =SUM(SMALL(B41:B52,{1,2,3,4,5,6}))/6 -> 5.5 | D41: 1500 | E41: 8 | F41: =SUM(SMALL(E41:E52,{1,2,3,4,5,6}))/6 -> 8 | G41: 2000 | H41: 4 | I41: =SUM(SMALL(H41:H52,{1,2,3,4,5,6}))/6 -> 1.3333333 | K41: 7 | L41: =SUM(SMALL(K41:K52,{1,2,3,4,5,6}))/6 -> 10 | M41: -1000 | N41: 23 | O41: =SUM(SMALL(N41:N52,{1,2,3,4,5,6}))/6 -> 10.325 | Q41: 8 | R41: 8.1666667 | V41: 2400 | W41: 5 | X41: =SUM(SMALL(W41:W52,{1,2,3,4,5,6}))/6 -> 7 | Y41: 300 | Z41: 24 | AA41: =SUM(SMALL(Z41:Z52,{1,2,3,4,5,6}))/6 -> 15.75 | AF41: 7 | AG41: =SUM(SMALL(AF41:AF52,{1,2,3,4,5,6}))/6 -> 7.4333333 | AI41: 11 | AJ41: 10.166667 | AL41: =16*1.1 -> 17.6 | AM41: =SUM(SMALL(AL41:AL52,{1,2,3,4,5,6}))/6 -> 10.761905 | AR41: 20 | AS41: =SUM(SMALL(AR41:AR52,{1,2,3,4,5,6}))/6 -> 12.833333 | AT41: 2500 | AU41: 21 | AV41: =SUM(SMALL(AU41:AU52,{1,2,3,4,5,6}))/6 -> 12 | BA41: 9 | BB41: 8.2666667 | BD41: 10 | BE41: =SUM(SMALL(BD41:BD52,{1,2,3,4,5,6}))/6 -> 14.333333
...
